Workbook
Name 개인일정구분: 공휴일!$E$2:$F$999
Name 공휴일구분: 공휴일!$B$2:$C$999
Name 사진꾸미기: INDEX(캘린더사진,MATCH(달력!$D$2,캘린더월,0),2)
Name 캘린더사진: 공휴일!#REF!
Name 캘린더월: 공휴일!#REF!

Sheet 보험나무
B1: ★ 본 자료는 보험나무 구독자들에게만 제공되는 자료로 외부배포 및 무단 공유는 금지입니다
B2: ★ 일정관리와 고객관리자료로 활용하시길 바랍니다 !
B4: 문의/건의사항 연락주세요 !
B7: 카카오톡 | C7: 인스타그램 | D7: 블로그 | E7: 유튜브

Sheet TIP
B1: ★ 수식입력란은 수정하지 못하게 해두었습니다 (시트 삭제시 수식이 망가질 수 있습니다) | H1: 비밀번호 : 7235
B2: ★ 설치된 엑셀 버전이 다르면 오류가 생길 수 있습니다 (저는 2016....)
B3: ★ ★ ★ 고객관리LIST에만 입력하시면 정보 자동입력 됩니다
B4: ★ [달력] 년/월 입력하시면 달력 자동변경됩니다
B5: ★ [달력] 주간 목표/실적 입력시 진행률 자동 표기됩니다
B7: ★ [고객정보 조회] - 이름입력시 [고객관리 LIST]에서 자동으로 정보 입력됩니다
B8: ★ 동명이인은 [고객정보조회(이름+생년월일)]에서 이름, 생년월일 6자리 입력하시면 정보 자동 표시 됩니다
B10: ★ 차량정보 갱신일 30일전에 눈에 띄는 색으로 바뀌게 해두었습니다
B11: ★ 상령일 30일 전 D-DAY 빨간글씨로 바뀌게 해두었습니다
B13: ★ [자동차보험] D-Day30 갱신일만 표기 됩니다 (*고객관리 리스트 갱신일 '년도'확인 필수)
B14: ★ [자동차보험] - 홈 - 편집 - 정렬 및 필터 - 다시적용 클릭 (*단축키 Ctrl + Alt + L)
B16: ★ 휴대폰-PC 동시 수정
B17: PC로 구글에 [스프레드시트]검색 후 [새 스프레드시트열기 - 파일 - 파일 가져오기]
... B20: 단축키 모음
B22: Ctrl | E22: Shift | H22: Alt
B23: 단축키 | C23: 기능 | E23: 단축키 | F23: 기능 | H23: 단축키 | I23: 기능
B24: Ctrl + A | C24: 전체 선택 | E24: Shift + Space | F24: 행 전체 선택 | H24: Alt + D | I24: 데이터 메뉴
B25: Ctrl + B | C25: 굵게 | E25: Shift + Enter | F25: 위 셀 이동 | H25: Alt + E | I25: 편집 메뉴
B26: Ctrl + C | C26: 복사 | E26: Shift + Tab | F26: 이전 셀 | H26: Alt + F | I26: 파일 메뉴
B27: Ctrl + D | C27: 아래로 채우기 | E27: Shift + F1 | F27: 도움말 | H27: Alt + H | I27: 도움말 메뉴
B28: Ctrl + E | C28: 빠른 채우기 | E28: Shift + F2 | F28: 메모 편집 | H28: Alt + I | I28: 삽입 메뉴
B29: Ctrl + F | C29: 찾기 | E29: Shift + F3 | F29: 함수 삽입 | H29: Alt + O | I29: 서식 메뉴
B30: Ctrl + G | C30: 이동 | E30: Shift + F4 | F30: 다음 찾기 | H30: Alt + T | I30: 도구 메뉴
B31: Ctrl + H | C31: 바꾸기 | E31: Shift + F8 | F31: 추가 선택 | H31: Alt + W | I31: 창 메뉴
B32: Ctrl + I | C32: 기울임 | E32: Shift + F9 | F32: 시트 재계산 | H32: Alt + Enter | I32: 셀 줄바꿈
B33: Ctrl + K | C33: 하이퍼링크 삽입 | E33: Shift + F10 | F33: 바로가기 메뉴 | H33: Alt + = | I33: 자동 합계
B34: Ctrl + N | C34: 새 통합문서 | E34: Shift + F11 | F34: 새 시트 | H34: Alt + ; | I34: 보이는 셀만 선택
... B42: Ctrl + W | C42: 창 닫기 | E42: Ctrl + Shift + ! | F42: 숫자 서식 | H42: Ctrl + Alt + F5 | I42: 피벗 새로고침
B43: Ctrl + X | C43: 잘라내기 | E43: Ctrl + Shift + @ | F43: 시간 서식
B44: Ctrl + Y | C44: 다시 실행 | E44: Ctrl + Shift + # | F44: 날짜 서식
B45: Ctrl + Z | C45: 실행 취소 | E45: Ctrl + Shift + $ | F45: 통화 서식
B46: Ctrl + 1 | C46: 셀 서식 | E46: Ctrl + Shift + % | F46: 백분율 서식
B47: Ctrl + 5 | C47: 취소선 | E47: Ctrl + Shift + ^ | F47: 지수 서식
B48: Ctrl + 0 | C48: 열 숨기기 | E48: Ctrl + Shift + ~ | F48: 일반 서식
B49: Ctrl + 9 | C49: 행 숨기기 | E49: Ctrl + Shift + ( | F49: 숨김 행 표시
B50: Ctrl + ` | C50: 수식 표시 전환 | E50: Ctrl + Shift + ) | F50: 숨김 열 표시
B51: Ctrl + F1 | C51: 리본 메뉴 표시/숨기기 | E51: Ctrl + Shift + : | F51: 현재 시간 입력
B52: Ctrl + F2 | C52: 인쇄 미리보기 | E52: Ctrl + Shift + Space | F52: 전체 시트 선택
B53: Ctrl + F3 | C53: 이름 관리자 | E53: Ctrl + Shift + 방향키 | F53: 데이터 끝까지 선택
B54: Ctrl + F4 | C54: 현재 창 닫기 | E54: Ctrl + Shift + P | F54: 글꼴 크기 변경
...

Sheet 달력
B2: 2026 | D2: 2
D3: =TEXT(DATE(B2,D2,1),"MMMM") -> February
B5: 일 Sunday | D5: 월 Monday | F5: 화 Tuesday | H5: 수 Wednesday | J5: 목 Thursday | L5: 금 Friday | N5: 토 Saturday | Q5: MEMO | Y5: 주차 | Z5: 목표 | AA5: 실적
B6: =IFERROR(VLOOKUP(C6,공휴일구분,2,0),"")&IF(IFERROR(VLOOKUP(C6,개인일정구분,2,0),"")<>""," / "&VLOOKUP(C6,개인일정구분,2,0),"") | C6: =DATE(B2,D2,1)-WEEKDAY(DATE(B2,D2,1))+1 -> 46054 | D6: =IFERROR(VLOOKUP(E6,공휴일구분,2,0),"")&IF(IFERROR(VLOOKUP(E6,개인일정구분,2,0),"")<>""," / "&VLOOKUP(E6,개인일정구분,2,0),"") | E6: =C6+1 -> 46055 | F6: =IFERROR(VLOOKUP(G6,공휴일구분,2,0),"")&IF(IFERROR(VLOOKUP(G6,개인일정구분,2,0),"")<>""," / "&VLOOKUP(G6,개인일정구분,2,0),"") | G6: =E6+1 -> 46056 | H6: =IFERROR(VLOOKUP(I6,공휴일구분,2,0),"")&IF(IFERROR(VLOOKUP(I6,개인일정구분,2,0),"")<>""," / "&VLOOKUP(I6,개인일정구분,2,0),"") | I6: =G6+1 -> 46057 | J6: =IFERROR(VLOOKUP(K6,공휴일구분,2,0),"")&IF(IFERROR(VLOOKUP(K6,개인일정구분,2,0),"")<>""," / "&VLOOKUP(K6,개인일정구분,2,0),"") | K6: =I6+1 -> 46058 | L6: =IFERROR(VLOOKUP(M6,공휴일구분,2,0),"")&IF(IFERROR(VLOOKUP(M6,개인일정구분,2,0),"")<>""," / "&VLOOKUP(M6,개인일정구분,2,0),"") | M6: =K6+1 -> 46059 | N6: =IFERROR(VLOOKUP(O6,공휴일구분,2,0),"")&IF(IFERROR(VLOOKUP(O6,개인일정구분,2,0),"")<>""," / "&VLOOKUP(O6,개인일정구분,2,0),"") | O6: =M6+1 -> 46060 | Y6: 1 | Z6: 5 | AA6: 5
B7: 메모하세용 | D7: 위에 숫자(년,월)변경하시면 | Z7: 30 | AA7: 20
D8: 달력 자동 변경됩니다 | Y8: 2
Y10: 3
B12: =IFERROR(VLOOKUP(C12,공휴일구분,2,0),"")&IF(IFERROR(VLOOKUP(C12,개인일정구분,2,0),"")<>""," / "&VLOOKUP(C12,개인일정구분,2,0),"") | C12: =C6+7 -> 46061 | D12: =IFERROR(VLOOKUP(E12,공휴일구분,2,0),"")&IF(IFERROR(VLOOKUP(E12,개인일정구분,2,0),"")<>""," / "&VLOOKUP(E12,개인일정구분,2,0),"") | E12: =C12+1 -> 46062 | F12: =IFERROR(VLOOKUP(G12,공휴일구분,2,0),"")&IF(IFERROR(VLOOKUP(G12,개인일정구분,2,0),"")<>""," / "&VLOOKUP(G12,개인일정구분,2,0),"") | G12: =E12+1 -> 46063 | H12: =IFERROR(VLOOKUP(I12,공휴일구분,2,0),"")&IF(IFERROR(VLOOKUP(I12,개인일정구분,2,0),"")<>""," / "&VLOOKUP(I12,개인일정구분,2,0),"") | I12: =G12+1 -> 46064 | J12: =IFERROR(VLOOKUP(K12,공휴일구분,2,0),"")&IF(IFERROR(VLOOKUP(K12,개인일정구분,2,0),"")<>""," / "&VLOOKUP(K12,개인일정구분,2,0),"") | K12: =I12+1 -> 46065 | L12: =IFERROR(VLOOKUP(M12,공휴일구분,2,0),"")&IF(IFERROR(VLOOKUP(M12,개인일정구분,2,0),"")<>""," / "&VLOOKUP(M12,개인일정구분,2,0),"") | M12: =K12+1 -> 46066 | N12: =IFERROR(VLOOKUP(O12,공휴일구분,2,0),"")&IF(IFERROR(VLOOKUP(O12,개인일정구분,2,0),"")<>""," / "&VLOOKUP(O12,개인일정구분,2,0),"") | O12: =M12+1 -> 46067 | Y12: 4
Y15: 월 누적 | Z15: =(SUM(Z6,Z8,Z10,Z12)) -> 5 | AA15: =(SUM(AA6,AA8,AA10,AA12)) -> 5
Z16: =(SUM(Z7,Z9,Z11,Z13)) -> 30 | AA16: =(SUM(AA7,AA9,AA11,AA13)) -> 20
B18: =IFERROR(VLOOKUP(C18,공휴일구분,2,0),"")&IF(IFERROR(VLOOKUP(C18,개인일정구분,2,0),"")<>""," / "&VLOOKUP(C18,개인일정구분,2,0),"") | C18: =C12+7 -> 46068 | D18: =IFERROR(VLOOKUP(E18,공휴일구분,2,0),"")&IF(IFERROR(VLOOKUP(E18,개인일정구분,2,0),"")<>""," / "&VLOOKUP(E18,개인일정구분,2,0),"") -> (휴)설날 연휴 | E18: =C18+1 -> 46069 | F18: =IFERROR(VLOOKUP(G18,공휴일구분,2,0),"")&IF(IFERROR(VLOOKUP(G18,개인일정구분,2,0),"")<>""," / "&VLOOKUP(G18,개인일정구분,2,0),"") -> (휴)설날 | G18: =E18+1 -> 46070 | H18: =IFERROR(VLOOKUP(I18,공휴일구분,2,0),"")&IF(IFERROR(VLOOKUP(I18,개인일정구분,2,0),"")<>""," / "&VLOOKUP(I18,개인일정구분,2,0),"") -> (휴)설날 연휴 | I18: =G18+1 -> 46071 | J18: =IFERROR(VLOOKUP(K18,공휴일구분,2,0),"")&IF(IFERROR(VLOOKUP(K18,개인일정구분,2,0),"")<>""," / "&VLOOKUP(K18,개인일정구분,2,0),"") | K18: =I18+1 -> 46072 | L18: =IFERROR(VLOOKUP(M18,공휴일구분,2,0),"")&IF(IFERROR(VLOOKUP(M18,개인일정구분,2,0),"")<>""," / "&VLOOKUP(M18,개인일정구분,2,0),"") | M18: =K18+1 -> 46073 | N18: =IFERROR(VLOOKUP(O18,공휴일구분,2,0),"")&IF(IFERROR(VLOOKUP(O18,개인일정구분,2,0),"")<>""," / "&VLOOKUP(O18,개인일정구분,2,0),"") | O18: =M18+1 -> 46074 | Y18: 건수 진행률
Y19: =IFERROR(AA15/Z15,0) -> 1
Y22: 금액 진행률
Y23: =IFERROR(AA16/Z16,0) -> 0.66666667
B24: =IFERROR(VLOOKUP(C24,공휴일구분,2,0),"")&IF(IFERROR(VLOOKUP(C24,개인일정구분,2,0),"")<>""," / "&VLOOKUP(C24,개인일정구분,2,0),"") | C24: =C18+7 -> 46075 | D24: =IFERROR(VLOOKUP(E24,공휴일구분,2,0),"")&IF(IFERROR(VLOOKUP(E24,개인일정구분,2,0),"")<>""," / "&VLOOKUP(E24,개인일정구분,2,0),"") | E24: =C24+1 -> 46076 | F24: =IFERROR(VLOOKUP(G24,공휴일구분,2,0),"")&IF(IFERROR(VLOOKUP(G24,개인일정구분,2,0),"")<>""," / "&VLOOKUP(G24,개인일정구분,2,0),"") | G24: =E24+1 -> 46077 | H24: =IFERROR(VLOOKUP(I24,공휴일구분,2,0),"")&IF(IFERROR(VLOOKUP(I24,개인일정구분,2,0),"")<>""," / "&VLOOKUP(I24,개인일정구분,2,0),"") | I24: =G24+1 -> 46078 | J24: =IFERROR(VLOOKUP(K24,공휴일구분,2,0),"")&IF(IFERROR(VLOOKUP(K24,개인일정구분,2,0),"")<>""," / "&VLOOKUP(K24,개인일정구분,2,0),"") | K24: =I24+1 -> 46079 | L24: =IFERROR(VLOOKUP(M24,공휴일구분,2,0),"")&IF(IFERROR(VLOOKUP(M24,개인일정구분,2,0),"")<>""," / "&VLOOKUP(M24,개인일정구분,2,0),"") | M24: =K24+1 -> 46080 | N24: =IFERROR(VLOOKUP(O24,공휴일구분,2,0),"")&IF(IFERROR(VLOOKUP(O24,개인일정구분,2,0),"")<>""," / "&VLOOKUP(O24,개인일정구분,2,0),"") | O24: =M24+1 -> 46081
Q26: =TEXT(DATE($B$2,$D$2-1,1),"MMM") -> Jan
Q27: 일 | R27: 월 | S27: 화 | T27: 수 | U27: 목 | V27: 금 | W27: 토
Q28: =DATE($B$2,$D$2-1,1)-WEEKDAY(DATE($B$2,$D$2-1,1))+1 -> 46019 | R28: =$Q28+COLUMN()-17 -> 46020 | S28: =$Q28+COLUMN()-17 -> 46021 | T28: =$Q28+COLUMN()-17 -> 46022 | U28: =$Q28+COLUMN()-17 -> 46023 | V28: =$Q28+COLUMN()-17 -> 46024 | W28: =$Q28+COLUMN()-17 -> 46025
Q29: =Q28+7 -> 46026 | R29: =$Q29+COLUMN()-17 -> 46027 | S29: =$Q29+COLUMN()-17 -> 46028 | T29: =$Q29+COLUMN()-17 -> 46029 | U29: =$Q29+COLUMN()-17 -> 46030 | V29: =$Q29+COLUMN()-17 -> 46031 | W29: =$Q29+COLUMN()-17 -> 46032
B30: =IFERROR(VLOOKUP(C30,공휴일구분,2,0),"")&IF(IFERROR(VLOOKUP(C30,개인일정구분,2,0),"")<>""," / "&VLOOKUP(C30,개인일정구분,2,0),"") -> (휴)삼일절 | C30: =C24+7 -> 46082 | D30: =IFERROR(VLOOKUP(E30,공휴일구분,2,0),"")&IF(IFERROR(VLOOKUP(E30,개인일정구분,2,0),"")<>""," / "&VLOOKUP(E30,개인일정구분,2,0),"") -> (휴)대체공휴일 | E30: =C30+1 -> 46083 | F30: =IFERROR(VLOOKUP(G30,공휴일구분,2,0),"")&IF(IFERROR(VLOOKUP(G30,개인일정구분,2,0),"")<>""," / "&VLOOKUP(G30,개인일정구분,2,0),"") | G30: =E30+1 -> 46084 | H30: =IFERROR(VLOOKUP(I30,공휴일구분,2,0),"")&IF(IFERROR(VLOOKUP(I30,개인일정구분,2,0),"")<>""," / "&VLOOKUP(I30,개인일정구분,2,0),"") | I30: =G30+1 -> 46085 | J30: =IFERROR(VLOOKUP(K30,공휴일구분,2,0),"")&IF(IFERROR(VLOOKUP(K30,개인일정구분,2,0),"")<>""," / "&VLOOKUP(K30,개인일정구분,2,0),"") | K30: =I30+1 -> 46086 | L30: =IFERROR(VLOOKUP(M30,공휴일구분,2,0),"")&IF(IFERROR(VLOOKUP(M30,개인일정구분,2,0),"")<>""," / "&VLOOKUP(M30,개인일정구분,2,0),"") | M30: =K30+1 -> 46087 | N30: =IFERROR(VLOOKUP(O30,공휴일구분,2,0),"")&IF(IFERROR(VLOOKUP(O30,개인일정구분,2,0),"")<>""," / "&VLOOKUP(O30,개인일정구분,2,0),"") | O30: =M30+1 -> 46088 | Q30: =Q29+7 -> 46033 | R30: =$Q30+COLUMN()-17 -> 46034 | S30: =$Q30+COLUMN()-17 -> 46035 | T30: =$Q30+COLUMN()-17 -> 46036 | U30: =$Q30+COLUMN()-17 -> 46037 | V30: =$Q30+COLUMN()-17 -> 46038 | W30: =$Q30+COLUMN()-17 -> 46039
Q31: =Q30+7 -> 46040 | R31: =$Q31+COLUMN()-17 -> 46041 | S31: =$Q31+COLUMN()-17 -> 46042 | T31: =$Q31+COLUMN()-17 -> 46043 | U31: =$Q31+COLUMN()-17 -> 46044 | V31: =$Q31+COLUMN()-17 -> 46045 | W31: =$Q31+COLUMN()-17 -> 46046
Q32: =Q31+7 -> 46047 | R32: =$Q32+COLUMN()-17 -> 46048 | S32: =$Q32+COLUMN()-17 -> 46049 | T32: =$Q32+COLUMN()-17 -> 46050 | U32: =$Q32+COLUMN()-17 -> 46051 | V32: =$Q32+COLUMN()-17 -> 46052 | W32: =$Q32+COLUMN()-17 -> 46053
Q33: =Q32+7 -> 46054 | R33: =$Q33+COLUMN()-17 -> 46055 | S33: =$Q33+COLUMN()-17 -> 46056 | T33: =$Q33+COLUMN()-17 -> 46057 | U33: =$Q33+COLUMN()-17 -> 46058 | V33: =$Q33+COLUMN()-17 -> 46059 | W33: =$Q33+COLUMN()-17 -> 46060
Q34: =TEXT(DATE($B$2,$D$2+1,1),"MMM") -> Mar
Q35: 일 | R35: 월 | S35: 화 | T35: 수 | U35: 목 | V35: 금 | W35: 토
B36: =IFERROR(VLOOKUP(C36,공휴일구분,2,0),"")&IF(IFERROR(VLOOKUP(C36,개인일정구분,2,0),"")<>""," / "&VLOOKUP(C36,개인일정구분,2,0),"") | C36: =C30+7 -> 46089 | D36: =IFERROR(VLOOKUP(E36,공휴일구분,2,0),"")&IF(IFERROR(VLOOKUP(E36,개인일정구분,2,0),"")<>""," / "&VLOOKUP(E36,개인일정구분,2,0),"") | E36: =C36+1 -> 46090 | F36: =IFERROR(VLOOKUP(G36,공휴일구분,2,0),"")&IF(IFERROR(VLOOKUP(G36,개인일정구분,2,0),"")<>""," / "&VLOOKUP(G36,개인일정구분,2,0),"") | G36: =E36+1 -> 46091 | H36: =IFERROR(VLOOKUP(I36,공휴일구분,2,0),"")&IF(IFERROR(VLOOKUP(I36,개인일정구분,2,0),"")<>""," / "&VLOOKUP(I36,개인일정구분,2,0),"") | I36: =G36+1 -> 46092 | J36: =IFERROR(VLOOKUP(K36,공휴일구분,2,0),"")&IF(IFERROR(VLOOKUP(K36,개인일정구분,2,0),"")<>""," / "&VLOOKUP(K36,개인일정구분,2,0),"") | K36: =I36+1 -> 46093 | L36: =IFERROR(VLOOKUP(M36,공휴일구분,2,0),"")&IF(IFERROR(VLOOKUP(M36,개인일정구분,2,0),"")<>""," / "&VLOOKUP(M36,개인일정구분,2,0),"") | M36: =K36+1 -> 46094 | N36: =IFERROR(VLOOKUP(O36,공휴일구분,2,0),"")&IF(IFERROR(VLOOKUP(O36,개인일정구분,2,0),"")<>""," / "&VLOOKUP(O36,개인일정구분,2,0),"") | O36: =M36+1 -> 46095 | Q36: =DATE($B$2,$D$2+1,1)-WEEKDAY(DATE($B$2,$D$2+1,1))+1 -> 46082 | R36: =$Q36+COLUMN()-17 -> 46083 | S36: =$Q36+COLUMN()-17 -> 46084 | T36: =$Q36+COLUMN()-17 -> 46085 | U36: =$Q36+COLUMN()-17 -> 46086 | V36: =$Q36+COLUMN()-17 -> 46087 | W36: =$Q36+COLUMN()-17 -> 46088
Q37: =Q36+7 -> 46089 | R37: =$Q37+COLUMN()-17 -> 46090 | S37: =$Q37+COLUMN()-17 -> 46091 | T37: =$Q37+COLUMN()-17 -> 46092 | U37: =$Q37+COLUMN()-17 -> 46093 | V37: =$Q37+COLUMN()-17 -> 46094 | W37: =$Q37+COLUMN()-17 -> 46095
Q38: =Q37+7 -> 46096 | R38: =$Q38+COLUMN()-17 -> 46097 | S38: =$Q38+COLUMN()-17 -> 46098 | T38: =$Q38+COLUMN()-17 -> 46099 | U38: =$Q38+COLUMN()-17 -> 46100 | V38: =$Q38+COLUMN()-17 -> 46101 | W38: =$Q38+COLUMN()-17 -> 46102
Q39: =Q38+7 -> 46103 | R39: =$Q39+COLUMN()-17 -> 46104 | S39: =$Q39+COLUMN()-17 -> 46105 | T39: =$Q39+COLUMN()-17 -> 46106 | U39: =$Q39+COLUMN()-17 -> 46107 | V39: =$Q39+COLUMN()-17 -> 46108 | W39: =$Q39+COLUMN()-17 -> 46109
Q40: =Q39+7 -> 46110 | R40: =$Q40+COLUMN()-17 -> 46111 | S40: =$Q40+COLUMN()-17 -> 46112 | T40: =$Q40+COLUMN()-17 -> 46113 | U40: =$Q40+COLUMN()-17 -> 46114 | V40: =$Q40+COLUMN()-17 -> 46115 | W40: =$Q40+COLUMN()-17 -> 46116
Q41: =Q40+7 -> 46117 | R41: =$Q41+COLUMN()-17 -> 46118 | S41: =$Q41+COLUMN()-17 -> 46119 | T41: =$Q41+COLUMN()-17 -> 46120 | U41: =$Q41+COLUMN()-17 -> 46121 | V41: =$Q41+COLUMN()-17 -> 46122 | W41: =$Q41+COLUMN()-17 -> 46123

Sheet 고객추가
AH1: =DATEDIF( EDATE( DATE( IF(OR(MID(TEXT(--C8,"0000000000000"),7,1)="3",MID(TEXT(--C8,"0000000000000"),7,1)="4"),2000,1900) +VALUE(LEFT(TEXT(--C8,"0000000000000"),2)), VALUE(MID(TEXT(--C8,"0000000000000"),3,2)), VALUE(MID(TEXT(--C8,"0000000000000"),5,2)) ), 6 ), TODAY(), "Y" ) -> #NUM!
B2: 고객 추가
B4: 이름 | E4: 주민번호 | H4: 전화번호
B6: 주소 | H6: 직업
B8: 메모

Sheet 고객관리 LIST
F1: 주민번호는 아이픈(-) 꼭 입력하셔야 합니다
C2: 고객 정보 관리 | W2: 갱신일 입력시 5월5일인 경우 : 5-5 로 입력하시면 됩니다 (*년도 확인 필수)
B4: 고객정보 | J4: 카드결제 | Q4: 보험금 청구 | V4: 차량정보
B5: 구분 | C5: 이름 | D5: 주민번호 | E5: 전화번호 | F5: 주소 | G5: 직업 | H5: 메모 | J5: 결제일 | K5: 명의자 | L5: 생년월일 | M5: 카드사 | N5: 카드번호 | O5: 유효기간 | Q5: 예금주 | R5: 주민번호 | S5: 은행 | T5: 계좌번호 | V5: 차량번호 | W5: 차종 | X5: 갱신일 | Y5: 보험사 | Z5: 운전자지정 | AA5: 할인 | AB5: E-Mail
B6: 지인 | C6: 배지연 | D6: 960901-2000000 | E6: 1076625117 | F6: 울산 | G6: 보험설계사 | H6: 보험나무 | J6: 13 | K6: =C6 -> 배지연 | L6: ='메뉴 추가'!J2 -> 960901 | M6: 신한카드 | N6: 111-1111-1111-11 | O6: 3/26 | Q6: =C6 -> 배지연 | R6: =D6 -> 960901-2000000 | S6: 농협은행 | T6: 333-3333-33333 | V6: 11가1111 | W6: ㄱ | X6: 46071 | Y6: 한화손해 | Z6: 가족 | AA6: 티맵 | AB6: bjy3204@naver.com
B7: DB | C7: 홍길동 | D7: 020514-3000000 | E7: 1012345678 | F7: 부산 | G7: 사무직 | J7: 10 | K7: =C7 -> 홍길동 | L7: ='메뉴 추가'!J3 -> 020514 | M7: 현대카드 | N7: 222-2222-2222 | O7: 8/30 | Q7: =C7 -> 홍길동 | R7: =D7 -> 020514-3000000 | S7: 전북은행 | T7: 444-4444-44444 | V7: 22나2222 | W7: ㄴ | X7: 46147 | Y7: 삼성화재 | Z7: 부부 | AA7: 블랙박스 | AB7: yoni0901@naver.com
K8: =C8 -> 0 | L8: ='메뉴 추가'!J4 | Q8: =C8 -> 0 | R8: =D8 -> 0
K9: =C9 -> 0 | L9: ='메뉴 추가'!J5 | Q9: =C9 -> 0 | R9: =D9 -> 0
K10: =C10 -> 0 | L10: ='메뉴 추가'!J6 | Q10: =C10 -> 0 | R10: =D10 -> 0
K11: =C11 -> 0 | L11: ='메뉴 추가'!J7 | Q11: =C11 -> 0 | R11: =D11 -> 0
K12: =C12 -> 0 | L12: ='메뉴 추가'!J8 | Q12: =C12 -> 0 | R12: =D12 -> 0
K13: =C13 -> 0 | L13: ='메뉴 추가'!J9 | Q13: =C13 -> 0 | R13: =D13 -> 0
K14: =C14 -> 0 | L14: ='메뉴 추가'!J10 | Q14: =C14 -> 0 | R14: =D14 -> 0
K15: =C15 -> 0 | L15: ='메뉴 추가'!J11 | Q15: =C15 -> 0 | R15: =D15 -> 0
K16: =C16 -> 0 | L16: ='메뉴 추가'!J12 | Q16: =C16 -> 0 | R16: =D16 -> 0
K17: =C17 -> 0 | L17: ='메뉴 추가'!J13 | Q17: =C17 -> 0 | R17: =D17 -> 0
K18: =C18 -> 0 | L18: ='메뉴 추가'!J14 | Q18: =C18 -> 0 | R18: =D18 -> 0
K19: =C19 -> 0 | L19: ='메뉴 추가'!J15 | Q19: =C19 -> 0 | R19: =D19 -> 0
... K32: =C32 -> 0 | L32: ='메뉴 추가'!J28 | Q32: =C32 -> 0 | R32: =D32 -> 0
F33: *이름 입력시 테두리 자동생성 됩니다 | K33: =C33 -> 0 | L33: ='메뉴 추가'!J29 | Q33: =C33 -> 0 | R33: =D33 -> 0
K34: =C34 -> 0 | L34: ='메뉴 추가'!J30 | Q34: =C34 -> 0 | R34: =D34 -> 0
K35: =C35 -> 0 | L35: ='메뉴 추가'!J31 | Q35: =C35 -> 0 | R35: =D35 -> 0
K36: =C36 -> 0 | L36: ='메뉴 추가'!J32 | Q36: =C36 -> 0 | R36: =D36 -> 0
K37: =C37 -> 0 | L37: ='메뉴 추가'!J33 | Q37: =C37 -> 0 | R37: =D37 -> 0
K38: =C38 -> 0 | L38: ='메뉴 추가'!J34 | Q38: =C38 -> 0 | R38: =D38 -> 0
K39: =C39 -> 0 | L39: ='메뉴 추가'!J35 | Q39: =C39 -> 0 | R39: =D39 -> 0
K40: =C40 -> 0 | L40: ='메뉴 추가'!J36 | Q40: =C40 -> 0 | R40: =D40 -> 0
K41: =C41 -> 0 | L41: ='메뉴 추가'!J37 | Q41: =C41 -> 0 | R41: =D41 -> 0
K42: =C42 -> 0 | L42: ='메뉴 추가'!J38 | Q42: =C42 -> 0 | R42: =D42 -> 0
K43: =C43 -> 0 | L43: ='메뉴 추가'!J39 | Q43: =C43 -> 0 | R43: =D43 -> 0
K44: =C44 -> 0 | L44: ='메뉴 추가'!J40 | Q44: =C44 -> 0 | R44: =D44 -> 0
K45: =C45 -> 0 | L45: ='메뉴 추가'!J41 | Q45: =C45 -> 0 | R45: =D45 -> 0
... K1677: =C1677 -> 0 | L1677: ='메뉴 추가'!J1673 | Q1677: =C1677 -> 0 | R1677: =D1677 -> 0
L1678: ='메뉴 추가'!J1674 | Q1678: =C1678 -> 0 | R1678: =D1678 -> 0
L1679: ='메뉴 추가'!J1675 | Q1679: =C1679 -> 0 | R1679: =D1679 -> 0
L1680: ='메뉴 추가'!J1676 | Q1680: =C1680 -> 0 | R1680: =D1680 -> 0
L1681: ='메뉴 추가'!J1677 | Q1681: =C1681 -> 0 | R1681: =D1681 -> 0
Q1682: =C1682 -> 0 | R1682: =D1682 -> 0
Q1683: =C1683 -> 0 | R1683: =D1683 -> 0
Q1684: =C1684 -> 0 | R1684: =D1684 -> 0
...

Sheet 고객정보 조회(이름+생년월일)
AH1: =DATEDIF( EDATE( DATE( IF(OR(MID(TEXT(--C8,"0000000000000"),7,1)="3",MID(TEXT(--C8,"0000000000000"),7,1)="4"),2000,1900) +VALUE(LEFT(TEXT(--C8,"0000000000000"),2)), VALUE(MID(TEXT(--C8,"0000000000000"),3,2)), VALUE(MID(TEXT(--C8,"0000000000000"),5,2)) ), 6 ), TODAY(), "Y" ) -> #VALUE!
B2: 고객 관리 카드
B4: 이름 | C4: 홍길동 | H4: =IF(J4="","", IF(J4-TODAY()>0,"D-"&(J4-TODAY()), IF(J4-TODAY()=0,"D-Day", "D+"&ABS(J4-TODAY())))) | I4: 상령일 | J4: =IF(C8="","", _xlfn.LET( _xlpm.s, SUBSTITUTE(TEXT(C8,"0000000000000"),"-",""), _xlpm.yy, VALUE(LEFT(_xlpm.s,2)), _xlpm.mm, VALUE(MID(_xlpm.s,3,2)), _xlpm.dd, VALUE(MID(_xlpm.s,5,2)), _xlpm.g, VALUE(MID(_xlpm.s,7,1)), _xlpm.dob, DATE(IF(_xlpm.g>=3,2000,1900)+_xlpm.yy, _xlpm.mm, _xlpm.dd), _xlpm.base, EDATE(_xlpm.dob,6), _xlpm.yr, YEAR(TODAY()) + IF(DATE(YEAR(TODAY()), MONTH(_xlpm.base), DAY(_xlpm.base)) < TODAY(), 1, 0), DATE(_xlpm.yr, MONTH(_xlpm.base), DAY(_xlpm.base)) ) )
B5: 생년월일 | C5: 생년월일 6자리
E6: {=IFERROR(INDEX('고객관리 LIST'!$B$6:$B$999, MATCH(1, ('고객관리 LIST'!$C$6:$C$999=$C$4)*('고객관리 LIST'!$A$6:$A$999=TEXT($C$5,"000000")), 0)), "")}
B7: 고객정보 | G7: 차량정보
B8: 주민번호 | C8: {=IFERROR( INDEX('고객관리 LIST'!$D$6:$D$999, MATCH(1, ('고객관리 LIST'!$C$6:$C$999=$C$4)* ('메뉴 추가'!$J$2:$J$995=TEXT($C$5,"000000")), 0) ), "")} | D8: 나이 | E8: =IF(C8="","", _xlfn.LET( _xlpm.s, SUBSTITUTE(TEXT(C8,"0000000000000"),"-",""), _xlpm.yy, VALUE(LEFT(_xlpm.s,2)), _xlpm.mm, VALUE(MID(_xlpm.s,3,2)), _xlpm.dd, VALUE(MID(_xlpm.s,5,2)), _xlpm.g, VALUE(MID(_xlpm.s,7,1)), _xlpm.birth, DATE(IF(_xlpm.g>=3,2000,1900)+_xlpm.yy, _xlpm.mm, _xlpm.dd), DATEDIF(_xlpm.birth, TODAY(), "Y") ) ) | G8: 차량번호 | H8: {=IFERROR(INDEX('고객관리 LIST'!$V$6:$V$999, MATCH(1, ('고객관리 LIST'!$C$6:$C$999=$C$4)*('메뉴 추가'!$J$2:$J$995=TEXT($C$5,"000000")), 0)), "")} | I8: 차종 | J8: {=IFERROR(INDEX('고객관리 LIST'!$W$6:$W$999, MATCH(1, ('고객관리 LIST'!$C$6:$C$999=$C$4)*('메뉴 추가'!$J$2:$J$995=TEXT($C$5,"000000")), 0)), "")}
B9: 전화번호 | C9: {=IFERROR( INDEX('고객관리 LIST'!$E$6:$E$999, MATCH(1, ('고객관리 LIST'!$C$6:$C$999=$C$4)* ('메뉴 추가'!$J$2:$J$995=TEXT($C$5,"000000")), 0) ), "")} | D9: E-Mail | E9: {=IFERROR(INDEX('고객관리 LIST'!$AB$6:$AB$999, MATCH(1, ('고객관리 LIST'!$C$6:$C$999=$C$4)*('메뉴 추가'!$J$2:$J$995=TEXT($C$5,"000000")), 0)), "")} | G9: 보험사 | H9: {=IFERROR(INDEX('고객관리 LIST'!$Y$6:$Y$999, MATCH(1, ('고객관리 LIST'!$C$6:$C$999=$C$4)*('메뉴 추가'!$J$2:$J$995=TEXT($C$5,"000000")), 0)), "")} | I9: 갱신일 | J9: {=IFERROR(INDEX('고객관리 LIST'!$X$6:$X$999, MATCH(1, ('고객관리 LIST'!$C$6:$C$999=$C$4)*('메뉴 추가'!$J$2:$J$995=TEXT($C$5,"000000")), 0)), "")}
B10: 직업 | C10: {=IFERROR( INDEX('고객관리 LIST'!$G$6:$G$999, MATCH(1, ('고객관리 LIST'!$C$6:$C$999=$C$4)* ('메뉴 추가'!$J$2:$J$995=TEXT($C$5,"000000")), 0) ), "")} | D10: 성별 | E10: =IF(OR(MID(TEXT(C8,"0000000000000"),8,1)="1",MID(TEXT(C8,"0000000000000"),8,1)="3"),"남","여") -> 여 | G10: 운전자지정 | H10: {=IFERROR(INDEX('고객관리 LIST'!$Z$6:$Z$999, MATCH(1, ('고객관리 LIST'!$C$6:$C$999=$C$4)*('메뉴 추가'!$J$2:$J$995=TEXT($C$5,"000000")), 0)), "")} | I10: 할인 | J10: {=IFERROR(INDEX('고객관리 LIST'!$AA$6:$AA$999, MATCH(1, ('고객관리 LIST'!$C$6:$C$999=$C$4)*('메뉴 추가'!$J$2:$J$995=TEXT($C$5,"000000")), 0)), "")}
B11: 주소 | C11: {=IFERROR(INDEX('고객관리 LIST'!$F$6:$F$999, MATCH(1, ('고객관리 LIST'!$C$6:$C$999=$C$4)*('메뉴 추가'!$J$2:$J$995=TEXT($C$5,"000000")), 0)), "")}
B12: 메모 | C12: {=IFERROR(INDEX('고객관리 LIST'!$H$6:$H$999, MATCH(1, ('고객관리 LIST'!$C$6:$C$999=$C$4)*('메뉴 추가'!$J$2:$J$995=TEXT($C$5,"000000")), 0)), "")}
B14: 카드정보 | G14: 보험금청구
B15: 결제일 | C15: {=IFERROR(INDEX('고객관리 LIST'!$J$6:$J$999, MATCH(1, ('고객관리 LIST'!$C$6:$C$999=$C$4)*('메뉴 추가'!$J$2:$J$995=TEXT($C$5,"000000")), 0)), "")} | D15: 카드주 | E15: {=IFERROR(INDEX('고객관리 LIST'!$K$6:$K$999, MATCH(1, ('고객관리 LIST'!$C$6:$C$999=$C$4)*('메뉴 추가'!$J$2:$J$995=TEXT($C$5,"000000")), 0)), "")} | G15: 예금주 | H15: {=IFERROR(INDEX('고객관리 LIST'!$Q$6:$Q$999, MATCH(1, ('고객관리 LIST'!$C$6:$C$999=$C$4)*('메뉴 추가'!$J$2:$J$995=TEXT($C$5,"000000")), 0)), "")} | I15: 주민번호 | J15: {=IFERROR(INDEX('고객관리 LIST'!$R$6:$R$999, MATCH(1, ('고객관리 LIST'!$C$6:$C$999=$C$4)*('메뉴 추가'!$J$2:$J$995=TEXT($C$5,"000000")), 0)), "")}
B16: 카드사 | C16: {=IFERROR(INDEX('고객관리 LIST'!$M$6:$M$999, MATCH(1, ('고객관리 LIST'!$C$6:$C$999=$C$4)*('메뉴 추가'!$J$2:$J$995=TEXT($C$5,"000000")), 0)), "")} | D16: 생년월일 | E16: {=IFERROR(INDEX('고객관리 LIST'!$L$6:$L$999, MATCH(1, ('고객관리 LIST'!$C$6:$C$999=$C$4)*('메뉴 추가'!$J$2:$J$995=TEXT($C$5,"000000")), 0)), "")} | G16: 은행 | H16: {=IFERROR(INDEX('고객관리 LIST'!$S$6:$S$999, MATCH(1, ('고객관리 LIST'!$C$6:$C$999=$C$4)*('메뉴 추가'!$J$2:$J$995=TEXT($C$5,"000000")), 0)), "")} | I16: 계좌번호 | J16: {=IFERROR(INDEX('고객관리 LIST'!$T$6:$T$999, MATCH(1, ('고객관리 LIST'!$C$6:$C$999=$C$4)*('메뉴 추가'!$J$2:$J$995=TEXT($C$5,"000000")), 0)), "")}
B17: 카드번호 | C17: {=IFERROR(INDEX('고객관리 LIST'!$N$6:$N$999, MATCH(1, ('고객관리 LIST'!$C$6:$C$999=$C$4)*('메뉴 추가'!$J$2:$J$995=TEXT($C$5,"000000")), 0)), "")} | D17: 유효기간 | E17: {=IFERROR(INDEX('고객관리 LIST'!$O$6:$O$999, MATCH(1, ('고객관리 LIST'!$C$6:$C$999=$C$4)*('메뉴 추가'!$J$2:$J$995=TEXT($C$5,"000000")), 0)), "")}
B19: 계약목록

Sheet 고객정보 조회
AH1: =DATEDIF( EDATE( DATE( IF(OR(MID(TEXT(--C7,"0000000000000"),7,1)="3",MID(TEXT(--C7,"0000000000000"),7,1)="4"),2000,1900) +VALUE(LEFT(TEXT(--C7,"0000000000000"),2)), VALUE(MID(TEXT(--C7,"0000000000000"),3,2)), VALUE(MID(TEXT(--C7,"0000000000000"),5,2)) ), 6 ), TODAY(), "Y" ) -> #VALUE!
B2: 고객 관리 카드
B4: 이름 | C4: 홍길동 | H4: =IF(J4="","", IF(J4-TODAY()>0,"D-"&(J4-TODAY()), IF(J4-TODAY()=0,"D-Day", "D+"&ABS(J4-TODAY())))) -> D-30 | I4: 상령일 | J4: =IF(C7="","", _xlfn.LET( _xlpm.s, SUBSTITUTE(TEXT(C7,"0000000000000"),"-",""), _xlpm.yy, VALUE(LEFT(_xlpm.s,2)), _xlpm.mm, VALUE(MID(_xlpm.s,3,2)), _xlpm.dd, VALUE(MID(_xlpm.s,5,2)), _xlpm.g, VALUE(MID(_xlpm.s,7,1)), _xlpm.dob, DATE(IF(_xlpm.g>=3,2000,1900)+_xlpm.yy, _xlpm.mm, _xlpm.dd), _xlpm.base, EDATE(_xlpm.dob,6), _xlpm.yr, YEAR(TODAY()) + IF(DATE(YEAR(TODAY()), MONTH(_xlpm.base), DAY(_xlpm.base)) < TODAY(), 1, 0), DATE(_xlpm.yr, MONTH(_xlpm.base), DAY(_xlpm.base)) ) ) -> 46340
E5: =IFERROR(INDEX('고객관리 LIST'!$B$6:$B$999, MATCH($C$4, '고객관리 LIST'!$C$6:$C$999, 0)), "") -> DB
B6: 고객정보 | G6: 차량정보
B7: 주민번호 | C7: =IFERROR(INDEX('고객관리 LIST'!$D$6:$D$999, MATCH($C$4, '고객관리 LIST'!$C$6:$C$999, 0)), "") -> 020514-3000000 | D7: 나이 | E7: =IF(C7="","", _xlfn.LET( _xlpm.s, SUBSTITUTE(TEXT(C7,"0000000000000"),"-",""), _xlpm.yy, VALUE(LEFT(_xlpm.s,2)), _xlpm.mm, VALUE(MID(_xlpm.s,3,2)), _xlpm.dd, VALUE(MID(_xlpm.s,5,2)), _xlpm.g, VALUE(MID(_xlpm.s,7,1)), _xlpm.dob, DATE(IF(_xlpm.g>=3,2000,1900)+_xlpm.yy, _xlpm.mm, _xlpm.dd), DATEDIF(_xlpm.dob, TODAY(), "Y") ) ) -> 24 | G7: 차량번호 | H7: =IFERROR(INDEX('고객관리 LIST'!$V$6:$V$999, MATCH($C$4, '고객관리 LIST'!$C$6:$C$999, 0)), "") -> 22나2222 | I7: 차종 | J7: =IFERROR(INDEX('고객관리 LIST'!$W$6:$W$999, MATCH($C$4, '고객관리 LIST'!$C$6:$C$999, 0)), "") -> ㄴ
B8: 전화번호 | C8: =IFERROR(INDEX('고객관리 LIST'!$E$6:$E$999, MATCH($C$4, '고객관리 LIST'!$C$6:$C$999, 0)), "") -> 1012345678 | D8: E-Mail | E8: =IFERROR(INDEX('고객관리 LIST'!$AB$6:$AB$999, MATCH($C$4, '고객관리 LIST'!$C$6:$C$999, 0)), "") -> yoni0901@naver.com | G8: 보험사 | H8: =IFERROR(INDEX('고객관리 LIST'!$Y$6:$Y$999, MATCH($C$4, '고객관리 LIST'!$C$6:$C$999, 0)), "") -> 삼성화재 | I8: 갱신일 | J8: =IFERROR(INDEX('고객관리 LIST'!$X$6:$X$999, MATCH($C$4, '고객관리 LIST'!$C$6:$C$999, 0)), "") -> 46147
B9: 직업 | C9: =IFERROR(INDEX('고객관리 LIST'!$G$6:$G$999, MATCH($C$4, '고객관리 LIST'!$C$6:$C$999, 0)), "") -> 사무직 | D9: 성별 | E9: =IF(OR(MID(TEXT(C7,"0000000000000"),8,1)="1",MID(TEXT(C7,"0000000000000"),8,1)="3"),"남","여") -> 남 | G9: 운전자지정 | H9: =IFERROR(INDEX('고객관리 LIST'!$Z$6:$Z$999, MATCH($C$4, '고객관리 LIST'!$C$6:$C$999, 0)), "") -> 부부 | I9: 할인 | J9: =IFERROR(INDEX('고객관리 LIST'!$AA$6:$AA$999, MATCH($C$4, '고객관리 LIST'!$C$6:$C$999, 0)), "") -> 블랙박스
B10: 주소 | C10: =IFERROR(INDEX('고객관리 LIST'!$F$6:$F$999, MATCH($C$4, '고객관리 LIST'!$C$6:$C$999, 0)), "") -> 부산
B11: 메모 | C11: =IFERROR(INDEX('고객관리 LIST'!$H$6:$H$999, MATCH($C$4, '고객관리 LIST'!$C$6:$C$999, 0)), "") -> 0
B13: 카드정보 | G13: 보험금청구
B14: 결제일 | C14: =IFERROR(INDEX('고객관리 LIST'!$J$6:$J$999, MATCH($C$4, '고객관리 LIST'!$C$6:$C$999, 0)), "") -> 10 | D14: 카드주 | E14: =IFERROR(INDEX('고객관리 LIST'!$K$6:$K$999, MATCH($C$4, '고객관리 LIST'!$C$6:$C$999, 0)), "") -> 홍길동 | G14: 예금주 | H14: =IFERROR(INDEX('고객관리 LIST'!$Q$6:$Q$999, MATCH($C$4, '고객관리 LIST'!$C$6:$C$999, 0)), "") -> 홍길동 | I14: 주민번호 | J14: =IFERROR(INDEX('고객관리 LIST'!$R$6:$R$999, MATCH($C$4, '고객관리 LIST'!$C$6:$C$999, 0)), "") -> 020514-3000000
B15: 카드사 | C15: =IFERROR(INDEX('고객관리 LIST'!$M$6:$M$999, MATCH($C$4, '고객관리 LIST'!$C$6:$C$999, 0)), "") -> 현대카드 | D15: 생년월일 | E15: =IFERROR(INDEX('고객관리 LIST'!$L$6:$L$999, MATCH($C$4, '고객관리 LIST'!$C$6:$C$999, 0)), "") -> 020514 | G15: 은행 | H15: =IFERROR(INDEX('고객관리 LIST'!$S$6:$S$999, MATCH($C$4, '고객관리 LIST'!$C$6:$C$999, 0)), "") -> 전북은행 | I15: 계좌번호 | J15: =IFERROR(INDEX('고객관리 LIST'!$T$6:$T$999, MATCH($C$4, '고객관리 LIST'!$C$6:$C$999, 0)), "") -> 444-4444-44444
B16: 카드번호 | C16: =IFERROR(INDEX('고객관리 LIST'!$N$6:$N$999, MATCH($C$4, '고객관리 LIST'!$C$6:$C$999, 0)), "") -> 222-2222-2222 | D16: 유효기간 | E16: =IFERROR(INDEX('고객관리 LIST'!$O$6:$O$999, MATCH($C$4, '고객관리 LIST'!$C$6:$C$999, 0)), "") -> 8/30

Sheet 자동차보험
G1: ★ [자동차보험] D-Day30 갱신일만 표기 됩니다 (*고객관리 리스트 갱신일 '년도'확인 필수)
D2: 자동차보험 | G2: ★ [자동차보험] - 홈 - 편집 - 정렬 및 필터 - 다시적용 클릭 (*단축키 Ctrl + Alt + L)
B5: 갱신일 | C5: 구분 | D5: 이름 | E5: 주민번호 | F5: 전화번호 | G5: 주소 | H5: 직업 | I5: 메모 | J5: 차량번호 | K5: 차종 | L5: 보험사 | M5: 운전자지정 | N5: 할인 | O5: E-Mail
A7: ='메뉴 추가'!I2 -> -239 | B7: ='고객관리 LIST'!X6 -> 46071 | C7: ='고객관리 LIST'!B6 -> 지인 | D7: ='고객관리 LIST'!C6 -> 배지연 | E7: ='고객관리 LIST'!D6 -> 960901-2000000 | F7: ='고객관리 LIST'!E6 -> 1076625117 | G7: ='고객관리 LIST'!F6 -> 울산 | H7: ='고객관리 LIST'!G6 -> 보험설계사 | I7: ='고객관리 LIST'!H6 -> 보험나무 | J7: ='고객관리 LIST'!V6 -> 11가1111 | K7: ='고객관리 LIST'!W6 -> ㄱ | L7: ='고객관리 LIST'!Y6 -> 한화손해 | M7: ='고객관리 LIST'!Z6 -> 가족 | N7: ='고객관리 LIST'!AA6 -> 티맵 | O7: ='고객관리 LIST'!AB6 -> bjy3204@naver.com
A8: ='메뉴 추가'!I3 -> -163 | B8: ='고객관리 LIST'!X7 -> 46147 | C8: ='고객관리 LIST'!B7 -> DB | D8: ='고객관리 LIST'!C7 -> 홍길동 | E8: ='고객관리 LIST'!D7 -> 020514-3000000 | F8: ='고객관리 LIST'!E7 -> 1012345678 | G8: ='고객관리 LIST'!F7 -> 부산 | H8: ='고객관리 LIST'!G7 -> 사무직 | I8: ='고객관리 LIST'!H7 -> 0 | J8: ='고객관리 LIST'!V7 -> 22나2222 | K8: ='고객관리 LIST'!W7 -> ㄴ | L8: ='고객관리 LIST'!Y7 -> 삼성화재 | M8: ='고객관리 LIST'!Z7 -> 부부 | N8: ='고객관리 LIST'!AA7 -> 블랙박스 | O8: ='고객관리 LIST'!AB7 -> yoni0901@naver.com
A9: ='메뉴 추가'!I4 -> -46310 | B9: ='고객관리 LIST'!X8 -> 0 | C9: ='고객관리 LIST'!B8 -> 0 | D9: ='고객관리 LIST'!C8 -> 0 | E9: ='고객관리 LIST'!D8 -> 0 | F9: ='고객관리 LIST'!E8 -> 0 | G9: ='고객관리 LIST'!F8 -> 0 | H9: ='고객관리 LIST'!G8 -> 0 | I9: ='고객관리 LIST'!H8 -> 0 | J9: ='고객관리 LIST'!V8 -> 0 | K9: ='고객관리 LIST'!W8 -> 0 | L9: ='고객관리 LIST'!Y8 -> 0 | M9: ='고객관리 LIST'!Z8 -> 0 | N9: ='고객관리 LIST'!AA8 -> 0 | O9: ='고객관리 LIST'!AB8 -> 0
A10: ='메뉴 추가'!I5 -> -46310 | B10: ='고객관리 LIST'!X9 -> 0 | C10: ='고객관리 LIST'!B9 -> 0 | D10: ='고객관리 LIST'!C9 -> 0 | E10: ='고객관리 LIST'!D9 -> 0 | F10: ='고객관리 LIST'!E9 -> 0 | G10: ='고객관리 LIST'!F9 -> 0 | H10: ='고객관리 LIST'!G9 -> 0 | I10: ='고객관리 LIST'!H9 -> 0 | J10: ='고객관리 LIST'!V9 -> 0 | K10: ='고객관리 LIST'!W9 -> 0 | L10: ='고객관리 LIST'!Y9 -> 0 | M10: ='고객관리 LIST'!Z9 -> 0 | N10: ='고객관리 LIST'!AA9 -> 0 | O10: ='고객관리 LIST'!AB9 -> 0
A11: ='메뉴 추가'!I6 -> -46310 | B11: ='고객관리 LIST'!X10 -> 0 | C11: ='고객관리 LIST'!B10 -> 0 | D11: ='고객관리 LIST'!C10 -> 0 | E11: ='고객관리 LIST'!D10 -> 0 | F11: ='고객관리 LIST'!E10 -> 0 | G11: ='고객관리 LIST'!F10 -> 0 | H11: ='고객관리 LIST'!G10 -> 0 | I11: ='고객관리 LIST'!H10 -> 0 | J11: ='고객관리 LIST'!V10 -> 0 | K11: ='고객관리 LIST'!W10 -> 0 | L11: ='고객관리 LIST'!Y10 -> 0 | M11: ='고객관리 LIST'!Z10 -> 0 | N11: ='고객관리 LIST'!AA10 -> 0 | O11: ='고객관리 LIST'!AB10 -> 0
A12: ='메뉴 추가'!I7 -> -46310 | B12: ='고객관리 LIST'!X11 -> 0 | C12: ='고객관리 LIST'!B11 -> 0 | D12: ='고객관리 LIST'!C11 -> 0 | E12: ='고객관리 LIST'!D11 -> 0 | F12: ='고객관리 LIST'!E11 -> 0 | G12: ='고객관리 LIST'!F11 -> 0 | H12: ='고객관리 LIST'!G11 -> 0 | I12: ='고객관리 LIST'!H11 -> 0 | J12: ='고객관리 LIST'!V11 -> 0 | K12: ='고객관리 LIST'!W11 -> 0 | L12: ='고객관리 LIST'!Y11 -> 0 | M12: ='고객관리 LIST'!Z11 -> 0 | N12: ='고객관리 LIST'!AA11 -> 0 | O12: ='고객관리 LIST'!AB11 -> 0
A13: ='메뉴 추가'!I8 -> -46310 | B13: ='고객관리 LIST'!X12 -> 0 | C13: ='고객관리 LIST'!B12 -> 0 | D13: ='고객관리 LIST'!C12 -> 0 | E13: ='고객관리 LIST'!D12 -> 0 | F13: ='고객관리 LIST'!E12 -> 0 | G13: ='고객관리 LIST'!F12 -> 0 | H13: ='고객관리 LIST'!G12 -> 0 | I13: ='고객관리 LIST'!H12 -> 0 | J13: ='고객관리 LIST'!V12 -> 0 | K13: ='고객관리 LIST'!W12 -> 0 | L13: ='고객관리 LIST'!Y12 -> 0 | M13: ='고객관리 LIST'!Z12 -> 0 | N13: ='고객관리 LIST'!AA12 -> 0 | O13: ='고객관리 LIST'!AB12 -> 0
A14: ='메뉴 추가'!I9 -> -46310 | B14: ='고객관리 LIST'!X13 -> 0 | C14: ='고객관리 LIST'!B13 -> 0 | D14: ='고객관리 LIST'!C13 -> 0 | E14: ='고객관리 LIST'!D13 -> 0 | F14: ='고객관리 LIST'!E13 -> 0 | G14: ='고객관리 LIST'!F13 -> 0 | H14: ='고객관리 LIST'!G13 -> 0 | I14: ='고객관리 LIST'!H13 -> 0 | J14: ='고객관리 LIST'!V13 -> 0 | K14: ='고객관리 LIST'!W13 -> 0 | L14: ='고객관리 LIST'!Y13 -> 0 | M14: ='고객관리 LIST'!Z13 -> 0 | N14: ='고객관리 LIST'!AA13 -> 0 | O14: ='고객관리 LIST'!AB13 -> 0
A15: ='메뉴 추가'!I10 -> -46310 | B15: ='고객관리 LIST'!X14 -> 0 | C15: ='고객관리 LIST'!B14 -> 0 | D15: ='고객관리 LIST'!C14 -> 0 | E15: ='고객관리 LIST'!D14 -> 0 | F15: ='고객관리 LIST'!E14 -> 0 | G15: ='고객관리 LIST'!F14 -> 0 | H15: ='고객관리 LIST'!G14 -> 0 | I15: ='고객관리 LIST'!H14 -> 0 | J15: ='고객관리 LIST'!V14 -> 0 | K15: ='고객관리 LIST'!W14 -> 0 | L15: ='고객관리 LIST'!Y14 -> 0 | M15: ='고객관리 LIST'!Z14 -> 0 | N15: ='고객관리 LIST'!AA14 -> 0 | O15: ='고객관리 LIST'!AB14 -> 0
A16: ='메뉴 추가'!I11 -> -46310 | B16: ='고객관리 LIST'!X15 -> 0 | C16: ='고객관리 LIST'!B15 -> 0 | D16: ='고객관리 LIST'!C15 -> 0 | E16: ='고객관리 LIST'!D15 -> 0 | F16: ='고객관리 LIST'!E15 -> 0 | G16: ='고객관리 LIST'!F15 -> 0 | H16: ='고객관리 LIST'!G15 -> 0 | I16: ='고객관리 LIST'!H15 -> 0 | J16: ='고객관리 LIST'!V15 -> 0 | K16: ='고객관리 LIST'!W15 -> 0 | L16: ='고객관리 LIST'!Y15 -> 0 | M16: ='고객관리 LIST'!Z15 -> 0 | N16: ='고객관리 LIST'!AA15 -> 0 | O16: ='고객관리 LIST'!AB15 -> 0
A17: ='메뉴 추가'!I12 -> -46310 | B17: ='고객관리 LIST'!X16 -> 0 | C17: ='고객관리 LIST'!B16 -> 0 | D17: ='고객관리 LIST'!C16 -> 0 | E17: ='고객관리 LIST'!D16 -> 0 | F17: ='고객관리 LIST'!E16 -> 0 | G17: ='고객관리 LIST'!F16 -> 0 | H17: ='고객관리 LIST'!G16 -> 0 | I17: ='고객관리 LIST'!H16 -> 0 | J17: ='고객관리 LIST'!V16 -> 0 | K17: ='고객관리 LIST'!W16 -> 0 | L17: ='고객관리 LIST'!Y16 -> 0 | M17: ='고객관리 LIST'!Z16 -> 0 | N17: ='고객관리 LIST'!AA16 -> 0 | O17: ='고객관리 LIST'!AB16 -> 0
A18: ='메뉴 추가'!I13 -> -46310 | B18: ='고객관리 LIST'!X17 -> 0 | C18: ='고객관리 LIST'!B17 -> 0 | D18: ='고객관리 LIST'!C17 -> 0 | E18: ='고객관리 LIST'!D17 -> 0 | F18: ='고객관리 LIST'!E17 -> 0 | G18: ='고객관리 LIST'!F17 -> 0 | H18: ='고객관리 LIST'!G17 -> 0 | I18: ='고객관리 LIST'!H17 -> 0 | J18: ='고객관리 LIST'!V17 -> 0 | K18: ='고객관리 LIST'!W17 -> 0 | L18: ='고객관리 LIST'!Y17 -> 0 | M18: ='고객관리 LIST'!Z17 -> 0 | N18: ='고객관리 LIST'!AA17 -> 0 | O18: ='고객관리 LIST'!AB17 -> 0
... A3421: ='메뉴 추가'!I3416 -> -46310 | B3421: ='고객관리 LIST'!X3420 -> 0 | C3421: ='고객관리 LIST'!B3420 -> 0 | D3421: ='고객관리 LIST'!C3420 -> 0 | E3421: ='고객관리 LIST'!D3420 -> 0 | F3421: ='고객관리 LIST'!E3420 -> 0 | G3421: ='고객관리 LIST'!F3420 -> 0 | H3421: ='고객관리 LIST'!G3420 -> 0 | I3421: ='고객관리 LIST'!H3420 -> 0 | J3421: ='고객관리 LIST'!V3420 -> 0 | K3421: ='고객관리 LIST'!W3420 -> 0 | L3421: ='고객관리 LIST'!Y3420 -> 0 | M3421: ='고객관리 LIST'!Z3420 -> 0 | N3421: ='고객관리 LIST'!AA3420 -> 0 | O3421: ='고객관리 LIST'!AB3420 -> 0
A3422: ='메뉴 추가'!I3417 -> -46310

Sheet 카드수납
G1: =DAY(TODAY()) -> 15 | I1: ★ [카드수납] 오늘 날짜만 표기 됩니다 (*고객관리 리스트 결제일확인 필수)
C2: 카드수납 | I2: ★ [카드수납] - 홈 - 편집 - 정렬 및 필터 - 다시적용 클릭 (*단축키 Ctrl + Alt + L)
B5: 결제일 | C5: 구분 | D5: 이름 | E5: 주민번호 | F5: 전화번호 | G5: 메모 | H5: 명의자 | I5: 생년월일 | J5: 카드사 | K5: 카드번호 | L5: 유효기간
A7: =B7=$G$1 -> FALSE | B7: ='고객관리 LIST'!J6 -> 13 | C7: ='고객관리 LIST'!B6 -> 지인 | D7: ='고객관리 LIST'!C6 -> 배지연 | E7: ='고객관리 LIST'!D6 -> 960901-2000000 | F7: ='고객관리 LIST'!E6 -> 1076625117 | G7: ='고객관리 LIST'!H6 -> 보험나무 | H7: ='고객관리 LIST'!K6 -> 배지연 | I7: ='고객관리 LIST'!L6 -> 960901 | J7: ='고객관리 LIST'!M6 -> 신한카드 | K7: ='고객관리 LIST'!N6 -> 111-1111-1111-11 | L7: ='고객관리 LIST'!O6 -> 3/26
A8: =B8=$G$1 -> FALSE | B8: ='고객관리 LIST'!J7 -> 10 | C8: ='고객관리 LIST'!B7 -> DB | D8: ='고객관리 LIST'!C7 -> 홍길동 | E8: ='고객관리 LIST'!D7 -> 020514-3000000 | F8: ='고객관리 LIST'!E7 -> 1012345678 | G8: ='고객관리 LIST'!H7 -> 0 | H8: ='고객관리 LIST'!K7 -> 홍길동 | I8: ='고객관리 LIST'!L7 -> 020514 | J8: ='고객관리 LIST'!M7 -> 현대카드 | K8: ='고객관리 LIST'!N7 -> 222-2222-2222 | L8: ='고객관리 LIST'!O7 -> 8/30
A9: =B9=$G$1 -> FALSE | B9: ='고객관리 LIST'!J8 -> 0 | C9: ='고객관리 LIST'!B8 -> 0 | D9: ='고객관리 LIST'!C8 -> 0 | E9: ='고객관리 LIST'!D8 -> 0 | F9: ='고객관리 LIST'!E8 -> 0 | G9: ='고객관리 LIST'!H8 -> 0 | H9: ='고객관리 LIST'!K8 -> 0 | I9: ='고객관리 LIST'!L8 | J9: ='고객관리 LIST'!M8 -> 0 | K9: ='고객관리 LIST'!N8 -> 0 | L9: ='고객관리 LIST'!O8 -> 0
A10: =B10=$G$1 -> FALSE | B10: ='고객관리 LIST'!J9 -> 0 | C10: ='고객관리 LIST'!B9 -> 0 | D10: ='고객관리 LIST'!C9 -> 0 | E10: ='고객관리 LIST'!D9 -> 0 | F10: ='고객관리 LIST'!E9 -> 0 | G10: ='고객관리 LIST'!H9 -> 0 | H10: ='고객관리 LIST'!K9 -> 0 | I10: ='고객관리 LIST'!L9 | J10: ='고객관리 LIST'!M9 -> 0 | K10: ='고객관리 LIST'!N9 -> 0 | L10: ='고객관리 LIST'!O9 -> 0
A11: =B11=$G$1 -> FALSE | B11: ='고객관리 LIST'!J10 -> 0 | C11: ='고객관리 LIST'!B10 -> 0 | D11: ='고객관리 LIST'!C10 -> 0 | E11: ='고객관리 LIST'!D10 -> 0 | F11: ='고객관리 LIST'!E10 -> 0 | G11: ='고객관리 LIST'!H10 -> 0 | H11: ='고객관리 LIST'!K10 -> 0 | I11: ='고객관리 LIST'!L10 | J11: ='고객관리 LIST'!M10 -> 0 | K11: ='고객관리 LIST'!N10 -> 0 | L11: ='고객관리 LIST'!O10 -> 0
A12: =B12=$G$1 -> FALSE | B12: ='고객관리 LIST'!J11 -> 0 | C12: ='고객관리 LIST'!B11 -> 0 | D12: ='고객관리 LIST'!C11 -> 0 | E12: ='고객관리 LIST'!D11 -> 0 | F12: ='고객관리 LIST'!E11 -> 0 | G12: ='고객관리 LIST'!H11 -> 0 | H12: ='고객관리 LIST'!K11 -> 0 | I12: ='고객관리 LIST'!L11 | J12: ='고객관리 LIST'!M11 -> 0 | K12: ='고객관리 LIST'!N11 -> 0 | L12: ='고객관리 LIST'!O11 -> 0
A13: =B13=$G$1 -> FALSE | B13: ='고객관리 LIST'!J12 -> 0 | C13: ='고객관리 LIST'!B12 -> 0 | D13: ='고객관리 LIST'!C12 -> 0 | E13: ='고객관리 LIST'!D12 -> 0 | F13: ='고객관리 LIST'!E12 -> 0 | G13: ='고객관리 LIST'!H12 -> 0 | H13: ='고객관리 LIST'!K12 -> 0 | I13: ='고객관리 LIST'!L12 | J13: ='고객관리 LIST'!M12 -> 0 | K13: ='고객관리 LIST'!N12 -> 0 | L13: ='고객관리 LIST'!O12 -> 0
A14: =B14=$G$1 -> FALSE | B14: ='고객관리 LIST'!J13 -> 0 | C14: ='고객관리 LIST'!B13 -> 0 | D14: ='고객관리 LIST'!C13 -> 0 | E14: ='고객관리 LIST'!D13 -> 0 | F14: ='고객관리 LIST'!E13 -> 0 | G14: ='고객관리 LIST'!H13 -> 0 | H14: ='고객관리 LIST'!K13 -> 0 | I14: ='고객관리 LIST'!L13 | J14: ='고객관리 LIST'!M13 -> 0 | K14: ='고객관리 LIST'!N13 -> 0 | L14: ='고객관리 LIST'!O13 -> 0
A15: =B15=$G$1 -> FALSE | B15: ='고객관리 LIST'!J14 -> 0 | C15: ='고객관리 LIST'!B14 -> 0 | D15: ='고객관리 LIST'!C14 -> 0 | E15: ='고객관리 LIST'!D14 -> 0 | F15: ='고객관리 LIST'!E14 -> 0 | G15: ='고객관리 LIST'!H14 -> 0 | H15: ='고객관리 LIST'!K14 -> 0 | I15: ='고객관리 LIST'!L14 | J15: ='고객관리 LIST'!M14 -> 0 | K15: ='고객관리 LIST'!N14 -> 0 | L15: ='고객관리 LIST'!O14 -> 0
A16: =B16=$G$1 -> FALSE | B16: ='고객관리 LIST'!J15 -> 0 | C16: ='고객관리 LIST'!B15 -> 0 | D16: ='고객관리 LIST'!C15 -> 0 | E16: ='고객관리 LIST'!D15 -> 0 | F16: ='고객관리 LIST'!E15 -> 0 | G16: ='고객관리 LIST'!H15 -> 0 | H16: ='고객관리 LIST'!K15 -> 0 | I16: ='고객관리 LIST'!L15 | J16: ='고객관리 LIST'!M15 -> 0 | K16: ='고객관리 LIST'!N15 -> 0 | L16: ='고객관리 LIST'!O15 -> 0
A17: =B17=$G$1 -> FALSE | B17: ='고객관리 LIST'!J16 -> 0 | C17: ='고객관리 LIST'!B16 -> 0 | D17: ='고객관리 LIST'!C16 -> 0 | E17: ='고객관리 LIST'!D16 -> 0 | F17: ='고객관리 LIST'!E16 -> 0 | G17: ='고객관리 LIST'!H16 -> 0 | H17: ='고객관리 LIST'!K16 -> 0 | I17: ='고객관리 LIST'!L16 | J17: ='고객관리 LIST'!M16 -> 0 | K17: ='고객관리 LIST'!N16 -> 0 | L17: ='고객관리 LIST'!O16 -> 0
A18: =B18=$G$1 -> FALSE | B18: ='고객관리 LIST'!J17 -> 0 | C18: ='고객관리 LIST'!B17 -> 0 | D18: ='고객관리 LIST'!C17 -> 0 | E18: ='고객관리 LIST'!D17 -> 0 | F18: ='고객관리 LIST'!E17 -> 0 | G18: ='고객관리 LIST'!H17 -> 0 | H18: ='고객관리 LIST'!K17 -> 0 | I18: ='고객관리 LIST'!L17 | J18: ='고객관리 LIST'!M17 -> 0 | K18: ='고객관리 LIST'!N17 -> 0 | L18: ='고객관리 LIST'!O17 -> 0
... A3612: =B3612=$G$1 -> FALSE | B3612: ='고객관리 LIST'!J3611 -> 0 | C3612: ='고객관리 LIST'!B3611 -> 0 | D3612: ='고객관리 LIST'!C3611 -> 0 | E3612: ='고객관리 LIST'!D3611 -> 0 | F3612: ='고객관리 LIST'!E3611 -> 0 | G3612: ='고객관리 LIST'!H3611 -> 0 | H3612: ='고객관리 LIST'!K3611 -> 0 | I3612: ='고객관리 LIST'!L3611 -> 0 | J3612: ='고객관리 LIST'!M3611 -> 0 | K3612: ='고객관리 LIST'!N3611 -> 0 | L3612: ='고객관리 LIST'!O3611 -> 0
B3613: ='고객관리 LIST'!J3612 -> 0 | C3613: ='고객관리 LIST'!B3612 -> 0 | D3613: ='고객관리 LIST'!C3612 -> 0 | E3613: ='고객관리 LIST'!D3612 -> 0 | F3613: ='고객관리 LIST'!E3612 -> 0 | G3613: ='고객관리 LIST'!H3612 -> 0 | H3613: ='고객관리 LIST'!K3612 -> 0 | I3613: ='고객관리 LIST'!L3612 -> 0 | J3613: ='고객관리 LIST'!M3612 -> 0 | K3613: ='고객관리 LIST'!N3612 -> 0 | L3613: ='고객관리 LIST'!O3612 -> 0
B3614: ='고객관리 LIST'!J3613 -> 0 | C3614: ='고객관리 LIST'!B3613 -> 0 | D3614: ='고객관리 LIST'!C3613 -> 0 | E3614: ='고객관리 LIST'!D3613 -> 0 | F3614: ='고객관리 LIST'!E3613 -> 0 | G3614: ='고객관리 LIST'!H3613 -> 0 | H3614: ='고객관리 LIST'!K3613 -> 0 | I3614: ='고객관리 LIST'!L3613 -> 0 | J3614: ='고객관리 LIST'!M3613 -> 0 | K3614: ='고객관리 LIST'!N3613 -> 0 | L3614: ='고객관리 LIST'!O3613 -> 0
B3615: ='고객관리 LIST'!J3614 -> 0 | C3615: ='고객관리 LIST'!B3614 -> 0 | D3615: ='고객관리 LIST'!C3614 -> 0 | E3615: ='고객관리 LIST'!D3614 -> 0 | F3615: ='고객관리 LIST'!E3614 -> 0 | G3615: ='고객관리 LIST'!H3614 -> 0 | H3615: ='고객관리 LIST'!K3614 -> 0 | I3615: ='고객관리 LIST'!L3614 -> 0 | J3615: ='고객관리 LIST'!M3614 -> 0 | K3615: ='고객관리 LIST'!N3614 -> 0 | L3615: ='고객관리 LIST'!O3614 -> 0
B3616: ='고객관리 LIST'!J3615 -> 0 | C3616: ='고객관리 LIST'!B3615 -> 0 | D3616: ='고객관리 LIST'!C3615 -> 0 | E3616: ='고객관리 LIST'!D3615 -> 0 | F3616: ='고객관리 LIST'!E3615 -> 0 | G3616: ='고객관리 LIST'!H3615 -> 0 | H3616: ='고객관리 LIST'!K3615 -> 0 | I3616: ='고객관리 LIST'!L3615 -> 0 | J3616: ='고객관리 LIST'!M3615 -> 0 | K3616: ='고객관리 LIST'!N3615 -> 0 | L3616: ='고객관리 LIST'!O3615 -> 0
B3617: ='고객관리 LIST'!J3616 -> 0 | C3617: ='고객관리 LIST'!B3616 -> 0 | D3617: ='고객관리 LIST'!C3616 -> 0 | E3617: ='고객관리 LIST'!D3616 -> 0 | F3617: ='고객관리 LIST'!E3616 -> 0 | G3617: ='고객관리 LIST'!H3616 -> 0 | H3617: ='고객관리 LIST'!K3616 -> 0 | I3617: ='고객관리 LIST'!L3616 -> 0 | J3617: ='고객관리 LIST'!M3616 -> 0 | K3617: ='고객관리 LIST'!N3616 -> 0 | L3617: ='고객관리 LIST'!O3616 -> 0
B3618: ='고객관리 LIST'!J3617 -> 0 | C3618: ='고객관리 LIST'!B3617 -> 0 | D3618: ='고객관리 LIST'!C3617 -> 0 | E3618: ='고객관리 LIST'!D3617 -> 0 | F3618: ='고객관리 LIST'!E3617 -> 0 | G3618: ='고객관리 LIST'!H3617 -> 0 | H3618: ='고객관리 LIST'!K3617 -> 0 | I3618: ='고객관리 LIST'!L3617 -> 0 | J3618: ='고객관리 LIST'!M3617 -> 0 | K3618: ='고객관리 LIST'!N3617 -> 0 | L3618: ='고객관리 LIST'!O3617 -> 0
B3619: ='고객관리 LIST'!J3618 -> 0 | C3619: ='고객관리 LIST'!B3618 -> 0 | D3619: ='고객관리 LIST'!C3618 -> 0 | E3619: ='고객관리 LIST'!D3618 -> 0 | F3619: ='고객관리 LIST'!E3618 -> 0 | G3619: ='고객관리 LIST'!H3618 -> 0 | H3619: ='고객관리 LIST'!K3618 -> 0 | I3619: ='고객관리 LIST'!L3618 -> 0 | J3619: ='고객관리 LIST'!M3618 -> 0 | K3619: ='고객관리 LIST'!N3618 -> 0 | L3619: ='고객관리 LIST'!O3618 -> 0
B3620: ='고객관리 LIST'!J3619 -> 0 | C3620: ='고객관리 LIST'!B3619 -> 0 | D3620: ='고객관리 LIST'!C3619 -> 0 | E3620: ='고객관리 LIST'!D3619 -> 0 | F3620: ='고객관리 LIST'!E3619 -> 0 | G3620: ='고객관리 LIST'!H3619 -> 0 | H3620: ='고객관리 LIST'!K3619 -> 0 | I3620: ='고객관리 LIST'!L3619 -> 0 | J3620: ='고객관리 LIST'!M3619 -> 0 | K3620: ='고객관리 LIST'!N3619 -> 0 | L3620: ='고객관리 LIST'!O3619 -> 0
B3621: ='고객관리 LIST'!J3620 -> 0 | C3621: ='고객관리 LIST'!B3620 -> 0 | D3621: ='고객관리 LIST'!C3620 -> 0 | E3621: ='고객관리 LIST'!D3620 -> 0 | F3621: ='고객관리 LIST'!E3620 -> 0 | G3621: ='고객관리 LIST'!H3620 -> 0 | H3621: ='고객관리 LIST'!K3620 -> 0 | I3621: ='고객관리 LIST'!L3620 -> 0 | J3621: ='고객관리 LIST'!M3620 -> 0 | K3621: ='고객관리 LIST'!N3620 -> 0 | L3621: ='고객관리 LIST'!O3620 -> 0
B3622: ='고객관리 LIST'!J3621 -> 0 | C3622: ='고객관리 LIST'!B3621 -> 0 | D3622: ='고객관리 LIST'!C3621 -> 0 | E3622: ='고객관리 LIST'!D3621 -> 0 | F3622: ='고객관리 LIST'!E3621 -> 0 | G3622: ='고객관리 LIST'!H3621 -> 0 | H3622: ='고객관리 LIST'!K3621 -> 0 | I3622: ='고객관리 LIST'!L3621 -> 0 | J3622: ='고객관리 LIST'!M3621 -> 0 | K3622: ='고객관리 LIST'!N3621 -> 0 | L3622: ='고객관리 LIST'!O3621 -> 0
B3623: ='고객관리 LIST'!J3622 -> 0 | C3623: ='고객관리 LIST'!B3622 -> 0 | D3623: ='고객관리 LIST'!C3622 -> 0 | E3623: ='고객관리 LIST'!D3622 -> 0 | F3623: ='고객관리 LIST'!E3622 -> 0 | G3623: ='고객관리 LIST'!H3622 -> 0 | H3623: ='고객관리 LIST'!K3622 -> 0 | I3623: ='고객관리 LIST'!L3622 -> 0 | J3623: ='고객관리 LIST'!M3622 -> 0 | K3623: ='고객관리 LIST'!N3622 -> 0 | L3623: ='고객관리 LIST'!O3622 -> 0
B3624: ='고객관리 LIST'!J3623 -> 0 | C3624: ='고객관리 LIST'!B3623 -> 0 | D3624: ='고객관리 LIST'!C3623 -> 0 | E3624: ='고객관리 LIST'!D3623 -> 0 | F3624: ='고객관리 LIST'!E3623 -> 0 | G3624: ='고객관리 LIST'!H3623 -> 0 | H3624: ='고객관리 LIST'!K3623 -> 0 | I3624: ='고객관리 LIST'!L3623 -> 0 | J3624: ='고객관리 LIST'!M3623 -> 0 | K3624: ='고객관리 LIST'!N3623 -> 0 | L3624: ='고객관리 LIST'!O3623 -> 0
... B4071: ='고객관리 LIST'!J4070 -> 0 | C4071: ='고객관리 LIST'!B4070 -> 0 | D4071: ='고객관리 LIST'!C4070 -> 0 | E4071: ='고객관리 LIST'!D4070 -> 0 | F4071: ='고객관리 LIST'!E4070 -> 0 | G4071: ='고객관리 LIST'!H4070 -> 0 | H4071: ='고객관리 LIST'!K4070 -> 0 | I4071: ='고객관리 LIST'!L4070 -> 0 | J4071: ='고객관리 LIST'!M4070 -> 0 | K4071: ='고객관리 LIST'!N4070 -> 0 | L4071: ='고객관리 LIST'!O4070 -> 0

Sheet 계약관리
F1: 주황색만 입력하시면 됩니다 (*회색은 고객관리LIST에서 자동추출) | AI1: =DATEDIF( EDATE( DATE( IF(OR(MID(TEXT(--C8,"0000000000000"),7,1)="3",MID(TEXT(--C8,"0000000000000"),7,1)="4"),2000,1900) +VALUE(LEFT(TEXT(--C8,"0000000000000"),2)), VALUE(MID(TEXT(--C8,"0000000000000"),3,2)), VALUE(MID(TEXT(--C8,"0000000000000"),5,2)) ), 6 ), TODAY(), "Y" ) -> #NUM!
C2: 계약목록
B4: 구분 | C4: 계약일 | D4: 계약자 | E4: 생년월일 | F4: 전화번호 | G4: 피보험자 | H4: 주민번호(피) | I4: 보험사 | J4: 보험료 | K4: 상품명 | L4: 메모
B5: =IFERROR(INDEX('고객관리 LIST'!$B$6:$B$999, MATCH(D5, '고객관리 LIST'!$C$6:$C$999, 0)), "") -> 지인 | C5: 46086 | D5: 배지연 | E5: 960901 | F5: =IFERROR(INDEX('고객관리 LIST'!$E$6:$E$999, MATCH(D5, '고객관리 LIST'!$C$6:$C$999, 0)), "") -> 1076625117 | G5: 홍길동 | H5: =IFERROR(INDEX('고객관리 LIST'!$D$6:$D$999, MATCH(G5, '고객관리 LIST'!$C$6:$C$999, 0)), "") -> 020514-3000000 | I5: 삼성화재 | J5: 160000 | K5: 새로고침 100세
B6: =IFERROR(INDEX('고객관리 LIST'!$B$6:$B$999, MATCH(D6, '고객관리 LIST'!$C$6:$C$999, 0)), "") -> DB | D6: 홍길동 | F6: =IFERROR(INDEX('고객관리 LIST'!$E$6:$E$999, MATCH(D6, '고객관리 LIST'!$C$6:$C$999, 0)), "") -> 1012345678 | G6: 배지연 | H6: =IFERROR(INDEX('고객관리 LIST'!$D$6:$D$999, MATCH(G6, '고객관리 LIST'!$C$6:$C$999, 0)), "") -> 960901-2000000
B7: =IFERROR(INDEX('고객관리 LIST'!$B$6:$B$999, MATCH(D7, '고객관리 LIST'!$C$6:$C$999, 0)), "") | E7: =IFERROR(INDEX('고객관리 LIST'!$D$6:$D$999, MATCH(D7, '고객관리 LIST'!$C$6:$C$999, 0)), "") | F7: =IFERROR(INDEX('고객관리 LIST'!$E$6:$E$999, MATCH(D7, '고객관리 LIST'!$C$6:$C$999, 0)), "") | H7: =IFERROR(INDEX('고객관리 LIST'!$D$6:$D$999, MATCH(G7, '고객관리 LIST'!$C$6:$C$999, 0)), "")
B8: =IFERROR(INDEX('고객관리 LIST'!$B$6:$B$999, MATCH(D8, '고객관리 LIST'!$C$6:$C$999, 0)), "") | E8: =IFERROR(INDEX('고객관리 LIST'!$D$6:$D$999, MATCH(D8, '고객관리 LIST'!$C$6:$C$999, 0)), "") | F8: =IFERROR(INDEX('고객관리 LIST'!$E$6:$E$999, MATCH(D8, '고객관리 LIST'!$C$6:$C$999, 0)), "") | H8: =IFERROR(INDEX('고객관리 LIST'!$D$6:$D$999, MATCH(G8, '고객관리 LIST'!$C$6:$C$999, 0)), "")
B9: =IFERROR(INDEX('고객관리 LIST'!$B$6:$B$999, MATCH(D9, '고객관리 LIST'!$C$6:$C$999, 0)), "") | E9: =IFERROR(INDEX('고객관리 LIST'!$D$6:$D$999, MATCH(D9, '고객관리 LIST'!$C$6:$C$999, 0)), "") | F9: =IFERROR(INDEX('고객관리 LIST'!$E$6:$E$999, MATCH(D9, '고객관리 LIST'!$C$6:$C$999, 0)), "") | H9: =IFERROR(INDEX('고객관리 LIST'!$D$6:$D$999, MATCH(G9, '고객관리 LIST'!$C$6:$C$999, 0)), "")
E10: =IFERROR(INDEX('고객관리 LIST'!$D$6:$D$999, MATCH(D10, '고객관리 LIST'!$C$6:$C$999, 0)), "") | F10: =IFERROR(INDEX('고객관리 LIST'!$E$6:$E$999, MATCH(D10, '고객관리 LIST'!$C$6:$C$999, 0)), "") | H10: =IFERROR(INDEX('고객관리 LIST'!$D$6:$D$999, MATCH(G10, '고객관리 LIST'!$C$6:$C$999, 0)), "")
E11: =IFERROR(INDEX('고객관리 LIST'!$D$6:$D$999, MATCH(D11, '고객관리 LIST'!$C$6:$C$999, 0)), "") | F11: =IFERROR(INDEX('고객관리 LIST'!$E$6:$E$999, MATCH(D11, '고객관리 LIST'!$C$6:$C$999, 0)), "")
E34: *이름 입력시 테두리 자동생성 됩니다

Sheet 메뉴 추가
B1: 아래쪽에 추가하면 메뉴 자동 추가 | I1: 지우면안됨
B2: 카드사 | C2: 은행 | D2: 자동차보험 | I2: ='고객관리 LIST'!X6-TODAY() -> -239 | J2: =LEFT('고객관리 LIST'!D6,6) -> 960901
B3: 신한카드 | C3: 국민은행 | D3: 삼성화재 | I3: ='고객관리 LIST'!X7-TODAY() -> -163 | J3: =LEFT('고객관리 LIST'!D7,6) -> 020514
B4: KB국민카드 | C4: 신한은행 | D4: 현대해상 | I4: ='고객관리 LIST'!X8-TODAY() -> -46310 | J4: =LEFT('고객관리 LIST'!D8,6)
B5: 삼성카드 | C5: 우리은행 | D5: DB손해 | I5: ='고객관리 LIST'!X9-TODAY() -> -46310 | J5: =LEFT('고객관리 LIST'!D9,6)
B6: 현대카드 | C6: 하나은행 | D6: KB손해 | I6: ='고객관리 LIST'!X10-TODAY() -> -46310 | J6: =LEFT('고객관리 LIST'!D10,6)
B7: 롯데카드 | C7: 농협 | D7: 메리츠화재 | I7: ='고객관리 LIST'!X11-TODAY() -> -46310 | J7: =LEFT('고객관리 LIST'!D11,6)
B8: 우리카드 | C8: 기업은행 | D8: 한화손해 | I8: ='고객관리 LIST'!X12-TODAY() -> -46310 | J8: =LEFT('고객관리 LIST'!D12,6)
B9: 하나카드 | C9: 부산은행 | D9: 흥국화재 | I9: ='고객관리 LIST'!X13-TODAY() -> -46310 | J9: =LEFT('고객관리 LIST'!D13,6)
B10: BC카드 | C10: 경남은행 | D10: 롯데손해 | I10: ='고객관리 LIST'!X14-TODAY() -> -46310 | J10: =LEFT('고객관리 LIST'!D14,6)
C11: 대구은행 | D11: AXA | I11: ='고객관리 LIST'!X15-TODAY() -> -46310 | J11: =LEFT('고객관리 LIST'!D15,6)
C12: 광주은행 | D12: 하나손해 | I12: ='고객관리 LIST'!X16-TODAY() -> -46310 | J12: =LEFT('고객관리 LIST'!D16,6)
C13: 전북은행 | D13: 캐롯 | I13: ='고객관리 LIST'!X17-TODAY() -> -46310 | J13: =LEFT('고객관리 LIST'!D17,6)
C14: 제주은행 | I14: ='고객관리 LIST'!X18-TODAY() -> -46310 | J14: =LEFT('고객관리 LIST'!D18,6)
C15: 수협 | I15: ='고객관리 LIST'!X19-TODAY() -> -46310 | J15: =LEFT('고객관리 LIST'!D19,6)
C16: 산업은행 | I16: ='고객관리 LIST'!X20-TODAY() -> -46310 | J16: =LEFT('고객관리 LIST'!D20,6)
C17: 씨티은행 | I17: ='고객관리 LIST'!X21-TODAY() -> -46310 | J17: =LEFT('고객관리 LIST'!D21,6)
C18: SC제일은행 | I18: ='고객관리 LIST'!X22-TODAY() -> -46310 | J18: =LEFT('고객관리 LIST'!D22,6)
C19: 카카오뱅크 | I19: ='고객관리 LIST'!X23-TODAY() -> -46310 | J19: =LEFT('고객관리 LIST'!D23,6)
C20: 케이뱅크 | I20: ='고객관리 LIST'!X24-TODAY() -> -46310 | J20: =LEFT('고객관리 LIST'!D24,6)
C21: 토스뱅크 | I21: ='고객관리 LIST'!X25-TODAY() -> -46310 | J21: =LEFT('고객관리 LIST'!D25,6)
C22: 농축협 | I22: ='고객관리 LIST'!X26-TODAY() -> -46310 | J22: =LEFT('고객관리 LIST'!D26,6)
C23: 새마을금고 | I23: ='고객관리 LIST'!X27-TODAY() -> -46310 | J23: =LEFT('고객관리 LIST'!D27,6)
C24: 우체국 | I24: ='고객관리 LIST'!X28-TODAY() -> -46310 | J24: =LEFT('고객관리 LIST'!D28,6)
I25: ='고객관리 LIST'!X29-TODAY() -> -46310 | J25: =LEFT('고객관리 LIST'!D29,6)
I26: ='고객관리 LIST'!X30-TODAY() -> -46310 | J26: =LEFT('고객관리 LIST'!D30,6)
I27: ='고객관리 LIST'!X31-TODAY() -> -46310 | J27: =LEFT('고객관리 LIST'!D31,6)
I28: ='고객관리 LIST'!X32-TODAY() -> -46310 | J28: =LEFT('고객관리 LIST'!D32,6)
I29: ='고객관리 LIST'!X33-TODAY() -> -46310 | J29: =LEFT('고객관리 LIST'!D33,6)
I30: ='고객관리 LIST'!X34-TODAY() -> -46310 | J30: =LEFT('고객관리 LIST'!D34,6)
I31: ='고객관리 LIST'!X35-TODAY() -> -46310 | J31: =LEFT('고객관리 LIST'!D35,6)
I32: ='고객관리 LIST'!X36-TODAY() -> -46310 | J32: =LEFT('고객관리 LIST'!D36,6)
I33: ='고객관리 LIST'!X37-TODAY() -> -46310 | J33: =LEFT('고객관리 LIST'!D37,6)
I34: ='고객관리 LIST'!X38-TODAY() -> -46310 | J34: =LEFT('고객관리 LIST'!D38,6)
I35: ='고객관리 LIST'!X39-TODAY() -> -46310 | J35: =LEFT('고객관리 LIST'!D39,6)
I36: ='고객관리 LIST'!X40-TODAY() -> -46310 | J36: =LEFT('고객관리 LIST'!D40,6)
... I2336: ='고객관리 LIST'!X2340-TODAY() -> -46310 | J2336: =LEFT('고객관리 LIST'!D2340,6)
I2337: ='고객관리 LIST'!X2341-TODAY() -> -46310
I2338: ='고객관리 LIST'!X2342-TODAY() -> -46310
I2339: ='고객관리 LIST'!X2343-TODAY() -> -46310
...

Sheet 공휴일
B2: 날짜 | C2: 구분 | E2: 날짜 | F2: 구분
B3: 46023 | C3: (휴)신정
B4: 46069 | C4: (휴)설날 연휴
B5: 46070 | C5: (휴)설날
B6: 46071 | C6: (휴)설날 연휴
B7: 46082 | C7: (휴)삼일절
B8: 46083 | C8: (휴)대체공휴일
B9: 46147 | C9: (휴)어린이날
B10: 46166 | C10: (휴)석가탄신일
B11: 46167 | C11: (휴)대체휴일
B12: 46176 | C12: (휴)전국동시지방선거
B13: 46179 | C13: (휴)현충일
B14: 46249 | C14: (휴)광복절
... B277: 51495 | C277: (휴)크리스마스
