Workbook

Sheet 보험나무
B1: ★ 본 자료는 보험나무 구독자들에게만 제공되는 자료로 외부배포 및 무단 공유는 금지입니다
B2: ★ 고객 초회상담과 보장분석, 비교제안, 소개요청 자료로 활용하시길 바랍니다 !
B4: 문의/건의사항 연락주세요 !
B7: 카카오톡 | C7: 인스타그램 | D7: 블로그 | E7: 유튜브

Sheet TIP
B1: ★ 수식입력란은 수정하시면 값 자동추출이 모두 망가집니다
B2: ★ 설치된 엑셀 버전이 다르면 오류가 생길 수 있습니다 (저는 2016)
B3: ★ ★ ★ 각 시트마다 설명 적어두었습니다 (메모는 삭제하고 사용하시면 됩니다)
B4: ★ ★ ★ 고객상담일지에 이름 입력하면 전체 시트 이름 변경됩니다
B6: 단축키 모음
B8: Ctrl | E8: Shift | H8: Alt
B9: 단축키 | C9: 기능 | E9: 단축키 | F9: 기능 | H9: 단축키 | I9: 기능
B10: Ctrl + A | C10: 전체 선택 | E10: Shift + Space | F10: 행 전체 선택 | H10: Alt + D | I10: 데이터 메뉴
B11: Ctrl + B | C11: 굵게 | E11: Shift + Enter | F11: 위 셀 이동 | H11: Alt + E | I11: 편집 메뉴
B12: Ctrl + C | C12: 복사 | E12: Shift + Tab | F12: 이전 셀 | H12: Alt + F | I12: 파일 메뉴
B13: Ctrl + D | C13: 아래로 채우기 | E13: Shift + F1 | F13: 도움말 | H13: Alt + H | I13: 도움말 메뉴
B14: Ctrl + E | C14: 빠른 채우기 | E14: Shift + F2 | F14: 메모 편집 | H14: Alt + I | I14: 삽입 메뉴
B15: Ctrl + F | C15: 찾기 | E15: Shift + F3 | F15: 함수 삽입 | H15: Alt + O | I15: 서식 메뉴
B16: Ctrl + G | C16: 이동 | E16: Shift + F4 | F16: 다음 찾기 | H16: Alt + T | I16: 도구 메뉴
B17: Ctrl + H | C17: 바꾸기 | E17: Shift + F8 | F17: 추가 선택 | H17: Alt + W | I17: 창 메뉴
B18: Ctrl + I | C18: 기울임 | E18: Shift + F9 | F18: 시트 재계산 | H18: Alt + Enter | I18: 셀 줄바꿈
B19: Ctrl + K | C19: 하이퍼링크 삽입 | E19: Shift + F10 | F19: 바로가기 메뉴 | H19: Alt + = | I19: 자동 합계
B20: Ctrl + N | C20: 새 통합문서 | E20: Shift + F11 | F20: 새 시트 | H20: Alt + ; | I20: 보이는 셀만 선택
... B28: Ctrl + W | C28: 창 닫기 | E28: Ctrl + Shift + ! | F28: 숫자 서식 | H28: Ctrl + Alt + F5 | I28: 피벗 새로고침
B29: Ctrl + X | C29: 잘라내기 | E29: Ctrl + Shift + @ | F29: 시간 서식
B30: Ctrl + Y | C30: 다시 실행 | E30: Ctrl + Shift + # | F30: 날짜 서식
B31: Ctrl + Z | C31: 실행 취소 | E31: Ctrl + Shift + $ | F31: 통화 서식
B32: Ctrl + 1 | C32: 셀 서식 | E32: Ctrl + Shift + % | F32: 백분율 서식
B33: Ctrl + 5 | C33: 취소선 | E33: Ctrl + Shift + ^ | F33: 지수 서식
B34: Ctrl + 0 | C34: 열 숨기기 | E34: Ctrl + Shift + ~ | F34: 일반 서식
B35: Ctrl + 9 | C35: 행 숨기기 | E35: Ctrl + Shift + ( | F35: 숨김 행 표시
B36: Ctrl + ` | C36: 수식 표시 전환 | E36: Ctrl + Shift + ) | F36: 숨김 열 표시
B37: Ctrl + F1 | C37: 리본 메뉴 표시/숨기기 | E37: Ctrl + Shift + : | F37: 현재 시간 입력
B38: Ctrl + F2 | C38: 인쇄 미리보기 | E38: Ctrl + Shift + Space | F38: 전체 시트 선택
B39: Ctrl + F3 | C39: 이름 관리자 | E39: Ctrl + Shift + 방향키 | F39: 데이터 끝까지 선택
B40: Ctrl + F4 | C40: 현재 창 닫기 | E40: Ctrl + Shift + P | F40: 글꼴 크기 변경
... B42: Ctrl + F6 | C42: 다음 통합문서 | E42: Ctrl + Shift + F6 | F42: 이전 통합문서로 이동
B43: Ctrl + F9 | C43: 전체 다시 계산
B44: Ctrl + F10 | C44: 창 최대/복원
B45: Ctrl + F11 | C45: 차트 시트
B46: Ctrl + F12 | C46: 다른 이름으로 저장
B47: Ctrl + → | C47: 오른쪽 한 단어 이동
B48: Ctrl + ← | C48: 왼쪽 한 단어 이동
B49: Ctrl + ↓ | C49: 아래 한 단락 이동
B50: Ctrl + ↑ | C50: 위로 한 단락 이동
...

Sheet 고객상담일지
A1: 고객 상담 일지
A3: ⭐개인정보동의 정보
A5: 이름 | B5: 홍길동 | D5: 주민번호
A6: 전화번호 | D6: 통신사
A7: 직업 | D7: 운전여부
A8: 주소
A10: ⭐계약전 알릴의무
A12: 근무처 | D12: 업종
A13: 키 | D13: 몸무게
A14: 이륜차 | D14: 레저활동
A16: ➤ 최근 3개월 이내에 의사로부터 진찰 또는 검사(건강검진포함) 를 통하여 다음과 같은 의료행위를 받은 사실이 있습니까?
A17: □ 질병확정진단 □ 질병의심소견 □ 치료 □ 입원 □ 수술(제왕절개포함) □ 투약
A19: ➤ 최근 3개월 이내에 마약을 사용하거나 혈압강하제, 신경안정제, 수면제, 각성제 (흥분제), 진통제 등약물을 상시 복용한 사실이 있습니까?
A21: ➤ 최근 1년 이내에 의사로부터 진찰 또는 검사를 받고 이를 통하여 추가검사(재검사)를 받은 사실이 있습니까?
A23: ➤ 최근 5년 이내에 의사로부터 진찰 또는 검사를 통하여 다음과 같은 의료행위를 받은 사실이 있습니까?
A24: □ 입원 □ 수술(제왕절개포함) □ 계속하여 7일 이상 치료 □ 계속하여 30일 이상투약
A26: 구분 | B26: 진단명 | C26: 치료내용 | F26: 치료기간
A27: 3개월
A28: 1년
A29: 5년
A31: ⭐차량정보
A33: 차량번호 | D33: 차종

Sheet 표지
M2: 이미지를 이용해 표지를 꾸며 보세요 !
C3: =고객상담일지!B5 -> 홍길동 | F3: 고객님을 위한
B8: 고객님이 가입하고 계신 보험을 종합적으로 분석하여
B9: 라이프스타일과 재무 상황을 반영한 최적의 맞춤 보장 설계를 제안해 드립니다
C13: =C3 -> 홍길동 | D13: 님 보험 현황
B15: 정상계약 | C15: =COUNTA(보장분석!E2:CA2) -> 1 | D15: 건
B16: 월 보험료 | C16: =보장분석!A5 -> 150000 | D16: 원
E17: =C18/C20 -> 0.0083333333
B18: 납입완료 | C18: =SUM(보장분석!E7:CA7) -> 450000 | D18: 원
B19: 납입예정 | C19: =SUM(보장분석!E6:CA6) -> 53550000 | D19: 원
B20: 총 보험료 | C20: =SUM(C18:C19) -> 54000000 | D20: 원
F36: 담당자 | G36: 배지연
F37: 소속 | G37: 보험나무
F38: 연락처 | G38: 010-7662-5117
F39: FAX | G39: 0504-444-5117
F40: E-MAIL | G40: yoni0901@naver.com

Sheet 보장분석
D1: 보험사 | E1: 한화생명
D2: 보험명 | E2: 한화생명 100세착한암보험
A3: 월 보험료 합계 | D3: 납입기간 | E3: 30
D4: 보장시작 | E4: 46023
A5: =SUM(E8:CA8) -> 150000 | D5: 보장종료 | E5: 71590 | F5: 아래 납입 예정 지우지마세요
D6: 납입예정 | E6: =IF(E4="","",MAX(E3*12-MIN(DATEDIF(E4,TODAY(),"m"),E3*12),0)*E8) -> 53550000 | F6: =IF(F4="","",MAX(F3*12-MIN(DATEDIF(F4,TODAY(),"m"),F3*12),0)*F8) | G6: =IF(G4="","",MAX(G3*12-MIN(DATEDIF(G4,TODAY(),"m"),G3*12),0)*G8) | H6: =IF(H4="","",MAX(H3*12-MIN(DATEDIF(H4,TODAY(),"m"),H3*12),0)*H8) | I6: =IF(I4="","",MAX(I3*12-MIN(DATEDIF(I4,TODAY(),"m"),I3*12),0)*I8) | J6: =IF(J4="","",MAX(J3*12-MIN(DATEDIF(J4,TODAY(),"m"),J3*12),0)*J8) | K6: =IF(K4="","",MAX(K3*12-MIN(DATEDIF(K4,TODAY(),"m"),K3*12),0)*K8) | L6: =IF(L4="","",MAX(L3*12-MIN(DATEDIF(L4,TODAY(),"m"),L3*12),0)*L8) | ... Y6: =IF(Y4="","",MAX(Y3*12-MIN(DATEDIF(Y4,TODAY(),"m"),Y3*12),0)*Y8)
D7: 납입완료 | E7: =IF(E4="","",IF(TODAY()<E4,0,MIN(DATEDIF(E4,TODAY(),"m"),E3*12)*E8)) -> 450000 | F7: =IF(F4="","",IF(TODAY()<F4,0,MIN(DATEDIF(F4,TODAY(),"m"),F3*12)*F8)) | G7: =IF(G4="","",IF(TODAY()<G4,0,MIN(DATEDIF(G4,TODAY(),"m"),G3*12)*G8)) | H7: =IF(H4="","",IF(TODAY()<H4,0,MIN(DATEDIF(H4,TODAY(),"m"),H3*12)*H8)) | I7: =IF(I4="","",IF(TODAY()<I4,0,MIN(DATEDIF(I4,TODAY(),"m"),I3*12)*I8)) | K7: =IF(K4="","",IF(TODAY()<K4,0,MIN(DATEDIF(K4,TODAY(),"m"),K3*12)*K8)) | L7: =IF(L4="","",IF(TODAY()<L4,0,MIN(DATEDIF(L4,TODAY(),"m"),L3*12)*L8)) | M7: =IF(M4="","",IF(TODAY()<M4,0,MIN(DATEDIF(M4,TODAY(),"m"),M3*12)*M8)) | N7: =IF(N4="","",IF(TODAY()<N4,0,MIN(DATEDIF(N4,TODAY(),"m"),N3*12)*N8)) | O7: =IF(O4="","",IF(TODAY()<O4,0,MIN(DATEDIF(O4,TODAY(),"m"),O3*12)*O8)) | P7: =IF(P4="","",IF(TODAY()<P4,0,MIN(DATEDIF(P4,TODAY(),"m"),P3*12)*P8)) | Q7: =IF(Q4="","",IF(TODAY()<Q4,0,MIN(DATEDIF(Q4,TODAY(),"m"),Q3*12)*Q8)) | R7: =IF(R4="","",IF(TODAY()<R4,0,MIN(DATEDIF(R4,TODAY(),"m"),R3*12)*R8)) | ... Y7: =IF(Y4="","",IF(TODAY()<Y4,0,MIN(DATEDIF(Y4,TODAY(),"m"),Y3*12)*Y8))
D8: 월 보험료 | E8: 150000
A9: 사망 | B9: 일반사망 | D9: =IF(SUM(E9:CA9)=0,"", IF(SUM(E9:CA9)>=10000, INT(SUM(E9:CA9)/10000)&"억"&IF(MOD(SUM(E9:CA9),10000)=0,"",TEXT(MOD(SUM(E9:CA9),10000),"#,##0")&"만원"), TEXT(SUM(E9:CA9),"#,##0")&"만원")) -> 3,000만원 | E9: 3000
B10: 질병사망 | D10: =IF(SUM(E10:CA10)=0,"", IF(SUM(E10:CA10)>=10000, INT(SUM(E10:CA10)/10000)&"억"&IF(MOD(SUM(E10:CA10),10000)=0,"",TEXT(MOD(SUM(E10:CA10),10000),"#,##0")&"만원"), TEXT(SUM(E10:CA10),"#,##0")&"만원"))
B11: 상해사망 | D11: =IF(SUM(E11:CA11)=0,"", IF(SUM(E11:CA11)>=10000, INT(SUM(E11:CA11)/10000)&"억"&IF(MOD(SUM(E11:CA11),10000)=0,"",TEXT(MOD(SUM(E11:CA11),10000),"#,##0")&"만원"), TEXT(SUM(E11:CA11),"#,##0")&"만원"))
A12: 장해 | B12: 질병후유장해(3%) | D12: =IF(SUM(E12:CA12)=0,"", IF(SUM(E12:CA12)>=10000, INT(SUM(E12:CA12)/10000)&"억"&IF(MOD(SUM(E12:CA12),10000)=0,"",TEXT(MOD(SUM(E12:CA12),10000),"#,##0")&"만원"), TEXT(SUM(E12:CA12),"#,##0")&"만원"))
B13: 질병후유장해(80%) | D13: =IF(SUM(E13:CA13)=0,"", IF(SUM(E13:CA13)>=10000, INT(SUM(E13:CA13)/10000)&"억"&IF(MOD(SUM(E13:CA13),10000)=0,"",TEXT(MOD(SUM(E13:CA13),10000),"#,##0")&"만원"), TEXT(SUM(E13:CA13),"#,##0")&"만원"))
B14: 상해후유장해(3%) | D14: =IF(SUM(E14:CA14)=0,"", IF(SUM(E14:CA14)>=10000, INT(SUM(E14:CA14)/10000)&"억"&IF(MOD(SUM(E14:CA14),10000)=0,"",TEXT(MOD(SUM(E14:CA14),10000),"#,##0")&"만원"), TEXT(SUM(E14:CA14),"#,##0")&"만원"))
B15: 상해후유장해(80%) | D15: =IF(SUM(E15:CA15)=0,"", IF(SUM(E15:CA15)>=10000, INT(SUM(E15:CA15)/10000)&"억"&IF(MOD(SUM(E15:CA15),10000)=0,"",TEXT(MOD(SUM(E15:CA15),10000),"#,##0")&"만원"), TEXT(SUM(E15:CA15),"#,##0")&"만원"))
A16: 치매 간병 | B16: 경증 치매 진단 | D16: =IF(SUM(E16:CA16)=0,"", IF(SUM(E16:CA16)>=10000, INT(SUM(E16:CA16)/10000)&"억"&IF(MOD(SUM(E16:CA16),10000)=0,"",TEXT(MOD(SUM(E16:CA16),10000),"#,##0")&"만원"), TEXT(SUM(E16:CA16),"#,##0")&"만원"))
B17: 시설급여 | D17: =IF(SUM(E17:CA17)=0,"", IF(SUM(E17:CA17)>=10000, INT(SUM(E17:CA17)/10000)&"억"&IF(MOD(SUM(E17:CA17),10000)=0,"",TEXT(MOD(SUM(E17:CA17),10000),"#,##0")&"만원"), TEXT(SUM(E17:CA17),"#,##0")&"만원"))
B18: 재가급여 | D18: =IF(SUM(E18:CA18)=0,"", IF(SUM(E18:CA18)>=10000, INT(SUM(E18:CA18)/10000)&"억"&IF(MOD(SUM(E18:CA18),10000)=0,"",TEXT(MOD(SUM(E18:CA18),10000),"#,##0")&"만원"), TEXT(SUM(E18:CA18),"#,##0")&"만원"))
B19: 질병 간병인 일당 | D19: =IF(SUM(E19:CA19)=0,"", IF(SUM(E19:CA19)>=10000, INT(SUM(E19:CA19)/10000)&"억"&IF(MOD(SUM(E19:CA19),10000)=0,"",TEXT(MOD(SUM(E19:CA19),10000),"#,##0")&"만원"), TEXT(SUM(E19:CA19),"#,##0")&"만원"))
B20: 상해 간병인 일당 | D20: =IF(SUM(E20:CA20)=0,"", IF(SUM(E20:CA20)>=10000, INT(SUM(E20:CA20)/10000)&"억"&IF(MOD(SUM(E20:CA20),10000)=0,"",TEXT(MOD(SUM(E20:CA20),10000),"#,##0")&"만원"), TEXT(SUM(E20:CA20),"#,##0")&"만원"))
A21: 암 | B21: 일반암 진단 | D21: =IF(SUM(E21:CA21)=0,"", IF(SUM(E21:CA21)>=10000, INT(SUM(E21:CA21)/10000)&"억"&IF(MOD(SUM(E21:CA21),10000)=0,"",TEXT(MOD(SUM(E21:CA21),10000),"#,##0")&"만원"), TEXT(SUM(E21:CA21),"#,##0")&"만원")) -> 3,000만원 | E21: 3000
B22: 유사암 진단 | D22: =IF(SUM(E22:CA22)=0,"", IF(SUM(E22:CA22)>=10000, INT(SUM(E22:CA22)/10000)&"억"&IF(MOD(SUM(E22:CA22),10000)=0,"",TEXT(MOD(SUM(E22:CA22),10000),"#,##0")&"만원"), TEXT(SUM(E22:CA22),"#,##0")&"만원")) -> 600만원 | E22: 600
B23: 암 주요 치료비 | D23: =IF(SUM(E23:CA23)=0,"", IF(SUM(E23:CA23)>=10000, INT(SUM(E23:CA23)/10000)&"억"&IF(MOD(SUM(E23:CA23),10000)=0,"",TEXT(MOD(SUM(E23:CA23),10000),"#,##0")&"만원"), TEXT(SUM(E23:CA23),"#,##0")&"만원"))
B24: 중입자 치료비 | D24: =IF(SUM(E24:CA24)=0,"", IF(SUM(E24:CA24)>=10000, INT(SUM(E24:CA24)/10000)&"억"&IF(MOD(SUM(E24:CA24),10000)=0,"",TEXT(MOD(SUM(E24:CA24),10000),"#,##0")&"만원"), TEXT(SUM(E24:CA24),"#,##0")&"만원"))
B25: 항암 방사선 치료비 | D25: =IF(SUM(E25:CA25)=0,"", IF(SUM(E25:CA25)>=10000, INT(SUM(E25:CA25)/10000)&"억"&IF(MOD(SUM(E25:CA25),10000)=0,"",TEXT(MOD(SUM(E25:CA25),10000),"#,##0")&"만원"), TEXT(SUM(E25:CA25),"#,##0")&"만원")) -> 1억 | E25: 10000
B26: 항암 약물 치료비 | D26: =IF(SUM(E26:CA26)=0,"", IF(SUM(E26:CA26)>=10000, INT(SUM(E26:CA26)/10000)&"억"&IF(MOD(SUM(E26:CA26),10000)=0,"",TEXT(MOD(SUM(E26:CA26),10000),"#,##0")&"만원"), TEXT(SUM(E26:CA26),"#,##0")&"만원")) -> 1억 | E26: 10000
A27: 뇌 | B27: 뇌혈관질환 진단 | D27: =IF(SUM(E27:CA27)=0,"", IF(SUM(E27:CA27)>=10000, INT(SUM(E27:CA27)/10000)&"억"&IF(MOD(SUM(E27:CA27),10000)=0,"",TEXT(MOD(SUM(E27:CA27),10000),"#,##0")&"만원"), TEXT(SUM(E27:CA27),"#,##0")&"만원")) -> 1,000만원 | E27: 1000
B28: 뇌졸증 진단 | D28: =IF(SUM(E28:CA28)=0,"", IF(SUM(E28:CA28)>=10000, INT(SUM(E28:CA28)/10000)&"억"&IF(MOD(SUM(E28:CA28),10000)=0,"",TEXT(MOD(SUM(E28:CA28),10000),"#,##0")&"만원"), TEXT(SUM(E28:CA28),"#,##0")&"만원"))
B29: 뇌출혈 진단 | D29: =IF(SUM(E29:CA29)=0,"", IF(SUM(E29:CA29)>=10000, INT(SUM(E29:CA29)/10000)&"억"&IF(MOD(SUM(E29:CA29),10000)=0,"",TEXT(MOD(SUM(E29:CA29),10000),"#,##0")&"만원"), TEXT(SUM(E29:CA29),"#,##0")&"만원")) -> 3,000만원 | E29: 3000
B30: 혈전용해치료비 | D30: =IF(SUM(E30:CA30)=0,"", IF(SUM(E30:CA30)>=10000, INT(SUM(E30:CA30)/10000)&"억"&IF(MOD(SUM(E30:CA30),10000)=0,"",TEXT(MOD(SUM(E30:CA30),10000),"#,##0")&"만원"), TEXT(SUM(E30:CA30),"#,##0")&"만원"))
B31: 뇌혈관 수술비 | D31: =IF(SUM(E31:CA31)=0,"", IF(SUM(E31:CA31)>=10000, INT(SUM(E31:CA31)/10000)&"억"&IF(MOD(SUM(E31:CA31),10000)=0,"",TEXT(MOD(SUM(E31:CA31),10000),"#,##0")&"만원"), TEXT(SUM(E31:CA31),"#,##0")&"만원")) -> 1,000만원 | E31: 1000
B32: 2대 주요 치료비 | D32: =IF(SUM(E32:CA32)=0,"", IF(SUM(E32:CA32)>=10000, INT(SUM(E32:CA32)/10000)&"억"&IF(MOD(SUM(E32:CA32),10000)=0,"",TEXT(MOD(SUM(E32:CA32),10000),"#,##0")&"만원"), TEXT(SUM(E32:CA32),"#,##0")&"만원"))
A33: 심장 | B33: 심혈관질환 진단 | D33: =IF(SUM(E33:CA33)=0,"", IF(SUM(E33:CA33)>=10000, INT(SUM(E33:CA33)/10000)&"억"&IF(MOD(SUM(E33:CA33),10000)=0,"",TEXT(MOD(SUM(E33:CA33),10000),"#,##0")&"만원"), TEXT(SUM(E33:CA33),"#,##0")&"만원"))
B34: 허혈성심장 진단 | D34: =IF(SUM(E34:CA34)=0,"", IF(SUM(E34:CA34)>=10000, INT(SUM(E34:CA34)/10000)&"억"&IF(MOD(SUM(E34:CA34),10000)=0,"",TEXT(MOD(SUM(E34:CA34),10000),"#,##0")&"만원"), TEXT(SUM(E34:CA34),"#,##0")&"만원"))
B35: 급성심근경색 진단 | D35: =IF(SUM(E35:CA35)=0,"", IF(SUM(E35:CA35)>=10000, INT(SUM(E35:CA35)/10000)&"억"&IF(MOD(SUM(E35:CA35),10000)=0,"",TEXT(MOD(SUM(E35:CA35),10000),"#,##0")&"만원"), TEXT(SUM(E35:CA35),"#,##0")&"만원")) -> 3,000만원 | E35: 3000
B36: 혈전용해치료비 | D36: =IF(SUM(E36:CA36)=0,"", IF(SUM(E36:CA36)>=10000, INT(SUM(E36:CA36)/10000)&"억"&IF(MOD(SUM(E36:CA36),10000)=0,"",TEXT(MOD(SUM(E36:CA36),10000),"#,##0")&"만원"), TEXT(SUM(E36:CA36),"#,##0")&"만원"))
B37: 허혈성심장 수술비 | D37: =IF(SUM(E37:CA37)=0,"", IF(SUM(E37:CA37)>=10000, INT(SUM(E37:CA37)/10000)&"억"&IF(MOD(SUM(E37:CA37),10000)=0,"",TEXT(MOD(SUM(E37:CA37),10000),"#,##0")&"만원"), TEXT(SUM(E37:CA37),"#,##0")&"만원")) -> 1,000만원 | E37: 1000
B38: 2대 주요 치료비 | D38: =IF(SUM(E38:CA38)=0,"", IF(SUM(E38:CA38)>=10000, INT(SUM(E38:CA38)/10000)&"억"&IF(MOD(SUM(E38:CA38),10000)=0,"",TEXT(MOD(SUM(E38:CA38),10000),"#,##0")&"만원"), TEXT(SUM(E38:CA38),"#,##0")&"만원"))
A39: 수술 | B39: 질병 수술비 | D39: =IF(SUM(E39:CA39)=0,"", IF(SUM(E39:CA39)>=10000, INT(SUM(E39:CA39)/10000)&"억"&IF(MOD(SUM(E39:CA39),10000)=0,"",TEXT(MOD(SUM(E39:CA39),10000),"#,##0")&"만원"), TEXT(SUM(E39:CA39),"#,##0")&"만원")) -> 50만원 | E39: 50
B40: 질병 종 수술비 | D40: 직접입력
...

Sheet 리모델링 후(보장)
D1: 보험사 | E1: 삼성화재
D2: 보험명 | E2: 새로고침100세
A3: 월 보험료 합계 | D3: 납입기간 | E3: 20
D4: 보장시작 | E4: 46023
A5: =SUM(E8:CA8) -> 100000 | D5: 보장종료 | E5: 71590 | F5: 아래 납입 예정 지우지마세요
D6: 납입예정 | E6: =IF(E4="","",MAX(E3*12-MIN(DATEDIF(E4,TODAY(),"m"),E3*12),0)*E8) -> 23700000 | F6: =IF(F4="","",MAX(F3*12-MIN(DATEDIF(F4,TODAY(),"m"),F3*12),0)*F8) | G6: =IF(G4="","",MAX(G3*12-MIN(DATEDIF(G4,TODAY(),"m"),G3*12),0)*G8) | H6: =IF(H4="","",MAX(H3*12-MIN(DATEDIF(H4,TODAY(),"m"),H3*12),0)*H8) | I6: =IF(I4="","",MAX(I3*12-MIN(DATEDIF(I4,TODAY(),"m"),I3*12),0)*I8) | J6: =IF(J4="","",MAX(J3*12-MIN(DATEDIF(J4,TODAY(),"m"),J3*12),0)*J8) | K6: =IF(K4="","",MAX(K3*12-MIN(DATEDIF(K4,TODAY(),"m"),K3*12),0)*K8) | L6: =IF(L4="","",MAX(L3*12-MIN(DATEDIF(L4,TODAY(),"m"),L3*12),0)*L8) | ... Y6: =IF(Y4="","",MAX(Y3*12-MIN(DATEDIF(Y4,TODAY(),"m"),Y3*12),0)*Y8)
D7: 납입완료 | E7: =IF(E4="","",IF(TODAY()<E4,0,MIN(DATEDIF(E4,TODAY(),"m"),E3*12)*E8)) -> 300000 | F7: =IF(F4="","",IF(TODAY()<F4,0,MIN(DATEDIF(F4,TODAY(),"m"),F3*12)*F8)) | G7: =IF(G4="","",IF(TODAY()<G4,0,MIN(DATEDIF(G4,TODAY(),"m"),G3*12)*G8)) | H7: =IF(H4="","",IF(TODAY()<H4,0,MIN(DATEDIF(H4,TODAY(),"m"),H3*12)*H8)) | I7: =IF(I4="","",IF(TODAY()<I4,0,MIN(DATEDIF(I4,TODAY(),"m"),I3*12)*I8)) | K7: =IF(K4="","",IF(TODAY()<K4,0,MIN(DATEDIF(K4,TODAY(),"m"),K3*12)*K8)) | L7: =IF(L4="","",IF(TODAY()<L4,0,MIN(DATEDIF(L4,TODAY(),"m"),L3*12)*L8)) | M7: =IF(M4="","",IF(TODAY()<M4,0,MIN(DATEDIF(M4,TODAY(),"m"),M3*12)*M8)) | N7: =IF(N4="","",IF(TODAY()<N4,0,MIN(DATEDIF(N4,TODAY(),"m"),N3*12)*N8)) | O7: =IF(O4="","",IF(TODAY()<O4,0,MIN(DATEDIF(O4,TODAY(),"m"),O3*12)*O8)) | P7: =IF(P4="","",IF(TODAY()<P4,0,MIN(DATEDIF(P4,TODAY(),"m"),P3*12)*P8)) | Q7: =IF(Q4="","",IF(TODAY()<Q4,0,MIN(DATEDIF(Q4,TODAY(),"m"),Q3*12)*Q8)) | R7: =IF(R4="","",IF(TODAY()<R4,0,MIN(DATEDIF(R4,TODAY(),"m"),R3*12)*R8)) | ... Y7: =IF(Y4="","",IF(TODAY()<Y4,0,MIN(DATEDIF(Y4,TODAY(),"m"),Y3*12)*Y8))
A8: ※ 리모델링 후 | D8: 월 보험료 | E8: 100000
A9: 사망 | B9: 일반사망 | D9: =IF(SUM(E9:CA9)=0,"", IF(SUM(E9:CA9)>=10000, INT(SUM(E9:CA9)/10000)&"억"&IF(MOD(SUM(E9:CA9),10000)=0,"",TEXT(MOD(SUM(E9:CA9),10000),"#,##0")&"만원"), TEXT(SUM(E9:CA9),"#,##0")&"만원"))
B10: 질병사망 | D10: =IF(SUM(E10:CA10)=0,"", IF(SUM(E10:CA10)>=10000, INT(SUM(E10:CA10)/10000)&"억"&IF(MOD(SUM(E10:CA10),10000)=0,"",TEXT(MOD(SUM(E10:CA10),10000),"#,##0")&"만원"), TEXT(SUM(E10:CA10),"#,##0")&"만원"))
B11: 상해사망 | D11: =IF(SUM(E11:CA11)=0,"", IF(SUM(E11:CA11)>=10000, INT(SUM(E11:CA11)/10000)&"억"&IF(MOD(SUM(E11:CA11),10000)=0,"",TEXT(MOD(SUM(E11:CA11),10000),"#,##0")&"만원"), TEXT(SUM(E11:CA11),"#,##0")&"만원"))
A12: 장해 | B12: 질병후유장해(3%) | D12: =IF(SUM(E12:CA12)=0,"", IF(SUM(E12:CA12)>=10000, INT(SUM(E12:CA12)/10000)&"억"&IF(MOD(SUM(E12:CA12),10000)=0,"",TEXT(MOD(SUM(E12:CA12),10000),"#,##0")&"만원"), TEXT(SUM(E12:CA12),"#,##0")&"만원"))
B13: 질병후유장해(80%) | D13: =IF(SUM(E13:CA13)=0,"", IF(SUM(E13:CA13)>=10000, INT(SUM(E13:CA13)/10000)&"억"&IF(MOD(SUM(E13:CA13),10000)=0,"",TEXT(MOD(SUM(E13:CA13),10000),"#,##0")&"만원"), TEXT(SUM(E13:CA13),"#,##0")&"만원"))
B14: 상해후유장해(3%) | D14: =IF(SUM(E14:CA14)=0,"", IF(SUM(E14:CA14)>=10000, INT(SUM(E14:CA14)/10000)&"억"&IF(MOD(SUM(E14:CA14),10000)=0,"",TEXT(MOD(SUM(E14:CA14),10000),"#,##0")&"만원"), TEXT(SUM(E14:CA14),"#,##0")&"만원"))
B15: 상해후유장해(80%) | D15: =IF(SUM(E15:CA15)=0,"", IF(SUM(E15:CA15)>=10000, INT(SUM(E15:CA15)/10000)&"억"&IF(MOD(SUM(E15:CA15),10000)=0,"",TEXT(MOD(SUM(E15:CA15),10000),"#,##0")&"만원"), TEXT(SUM(E15:CA15),"#,##0")&"만원"))
A16: 치매 간병 | B16: 경증 치매 진단 | D16: =IF(SUM(E16:CA16)=0,"", IF(SUM(E16:CA16)>=10000, INT(SUM(E16:CA16)/10000)&"억"&IF(MOD(SUM(E16:CA16),10000)=0,"",TEXT(MOD(SUM(E16:CA16),10000),"#,##0")&"만원"), TEXT(SUM(E16:CA16),"#,##0")&"만원"))
B17: 시설급여 | D17: =IF(SUM(E17:CA17)=0,"", IF(SUM(E17:CA17)>=10000, INT(SUM(E17:CA17)/10000)&"억"&IF(MOD(SUM(E17:CA17),10000)=0,"",TEXT(MOD(SUM(E17:CA17),10000),"#,##0")&"만원"), TEXT(SUM(E17:CA17),"#,##0")&"만원"))
B18: 재가급여 | D18: =IF(SUM(E18:CA18)=0,"", IF(SUM(E18:CA18)>=10000, INT(SUM(E18:CA18)/10000)&"억"&IF(MOD(SUM(E18:CA18),10000)=0,"",TEXT(MOD(SUM(E18:CA18),10000),"#,##0")&"만원"), TEXT(SUM(E18:CA18),"#,##0")&"만원"))
B19: 질병 간병인 일당 | D19: =IF(SUM(E19:CA19)=0,"", IF(SUM(E19:CA19)>=10000, INT(SUM(E19:CA19)/10000)&"억"&IF(MOD(SUM(E19:CA19),10000)=0,"",TEXT(MOD(SUM(E19:CA19),10000),"#,##0")&"만원"), TEXT(SUM(E19:CA19),"#,##0")&"만원")) -> 15만원 | E19: 15
B20: 상해 간병인 일당 | D20: =IF(SUM(E20:CA20)=0,"", IF(SUM(E20:CA20)>=10000, INT(SUM(E20:CA20)/10000)&"억"&IF(MOD(SUM(E20:CA20),10000)=0,"",TEXT(MOD(SUM(E20:CA20),10000),"#,##0")&"만원"), TEXT(SUM(E20:CA20),"#,##0")&"만원")) -> 15만원 | E20: 15
A21: 암 | B21: 일반암 진단 | D21: =IF(SUM(E21:CA21)=0,"", IF(SUM(E21:CA21)>=10000, INT(SUM(E21:CA21)/10000)&"억"&IF(MOD(SUM(E21:CA21),10000)=0,"",TEXT(MOD(SUM(E21:CA21),10000),"#,##0")&"만원"), TEXT(SUM(E21:CA21),"#,##0")&"만원")) -> 5,000만원 | E21: 5000
B22: 유사암 진단 | D22: =IF(SUM(E22:CA22)=0,"", IF(SUM(E22:CA22)>=10000, INT(SUM(E22:CA22)/10000)&"억"&IF(MOD(SUM(E22:CA22),10000)=0,"",TEXT(MOD(SUM(E22:CA22),10000),"#,##0")&"만원"), TEXT(SUM(E22:CA22),"#,##0")&"만원")) -> 1,000만원 | E22: 1000
B23: 암 주요 치료비 | D23: =IF(SUM(E23:CA23)=0,"", IF(SUM(E23:CA23)>=10000, INT(SUM(E23:CA23)/10000)&"억"&IF(MOD(SUM(E23:CA23),10000)=0,"",TEXT(MOD(SUM(E23:CA23),10000),"#,##0")&"만원"), TEXT(SUM(E23:CA23),"#,##0")&"만원")) -> 1,000만원 | E23: 1000
B24: 중입자 치료비 | D24: =IF(SUM(E24:CA24)=0,"", IF(SUM(E24:CA24)>=10000, INT(SUM(E24:CA24)/10000)&"억"&IF(MOD(SUM(E24:CA24),10000)=0,"",TEXT(MOD(SUM(E24:CA24),10000),"#,##0")&"만원"), TEXT(SUM(E24:CA24),"#,##0")&"만원")) -> 5,000만원 | E24: 5000
B25: 항암 방사선 치료비 | D25: =IF(SUM(E25:CA25)=0,"", IF(SUM(E25:CA25)>=10000, INT(SUM(E25:CA25)/10000)&"억"&IF(MOD(SUM(E25:CA25),10000)=0,"",TEXT(MOD(SUM(E25:CA25),10000),"#,##0")&"만원"), TEXT(SUM(E25:CA25),"#,##0")&"만원"))
B26: 항암 약물 치료비 | D26: =IF(SUM(E26:CA26)=0,"", IF(SUM(E26:CA26)>=10000, INT(SUM(E26:CA26)/10000)&"억"&IF(MOD(SUM(E26:CA26),10000)=0,"",TEXT(MOD(SUM(E26:CA26),10000),"#,##0")&"만원"), TEXT(SUM(E26:CA26),"#,##0")&"만원"))
A27: 뇌 | B27: 뇌혈관질환 진단 | D27: =IF(SUM(E27:CA27)=0,"", IF(SUM(E27:CA27)>=10000, INT(SUM(E27:CA27)/10000)&"억"&IF(MOD(SUM(E27:CA27),10000)=0,"",TEXT(MOD(SUM(E27:CA27),10000),"#,##0")&"만원"), TEXT(SUM(E27:CA27),"#,##0")&"만원")) -> 1,000만원 | E27: 1000
B28: 뇌졸증 진단 | D28: =IF(SUM(E28:CA28)=0,"", IF(SUM(E28:CA28)>=10000, INT(SUM(E28:CA28)/10000)&"억"&IF(MOD(SUM(E28:CA28),10000)=0,"",TEXT(MOD(SUM(E28:CA28),10000),"#,##0")&"만원"), TEXT(SUM(E28:CA28),"#,##0")&"만원")) -> 1,000만원 | E28: 1000
B29: 뇌출혈 진단 | D29: =IF(SUM(E29:CA29)=0,"", IF(SUM(E29:CA29)>=10000, INT(SUM(E29:CA29)/10000)&"억"&IF(MOD(SUM(E29:CA29),10000)=0,"",TEXT(MOD(SUM(E29:CA29),10000),"#,##0")&"만원"), TEXT(SUM(E29:CA29),"#,##0")&"만원"))
B30: 혈전용해치료비 | D30: =IF(SUM(E30:CA30)=0,"", IF(SUM(E30:CA30)>=10000, INT(SUM(E30:CA30)/10000)&"억"&IF(MOD(SUM(E30:CA30),10000)=0,"",TEXT(MOD(SUM(E30:CA30),10000),"#,##0")&"만원"), TEXT(SUM(E30:CA30),"#,##0")&"만원"))
B31: 뇌혈관 수술비 | D31: =IF(SUM(E31:CA31)=0,"", IF(SUM(E31:CA31)>=10000, INT(SUM(E31:CA31)/10000)&"억"&IF(MOD(SUM(E31:CA31),10000)=0,"",TEXT(MOD(SUM(E31:CA31),10000),"#,##0")&"만원"), TEXT(SUM(E31:CA31),"#,##0")&"만원"))
B32: 2대 주요 치료비 | D32: =IF(SUM(E32:CA32)=0,"", IF(SUM(E32:CA32)>=10000, INT(SUM(E32:CA32)/10000)&"억"&IF(MOD(SUM(E32:CA32),10000)=0,"",TEXT(MOD(SUM(E32:CA32),10000),"#,##0")&"만원"), TEXT(SUM(E32:CA32),"#,##0")&"만원")) -> 2,000만원 | E32: 2000
A33: 심장 | B33: 심혈관질환 진단 | D33: =IF(SUM(E33:CA33)=0,"", IF(SUM(E33:CA33)>=10000, INT(SUM(E33:CA33)/10000)&"억"&IF(MOD(SUM(E33:CA33),10000)=0,"",TEXT(MOD(SUM(E33:CA33),10000),"#,##0")&"만원"), TEXT(SUM(E33:CA33),"#,##0")&"만원")) -> 1,000만원 | E33: 1000
B34: 허혈성심장 진단 | D34: =IF(SUM(E34:CA34)=0,"", IF(SUM(E34:CA34)>=10000, INT(SUM(E34:CA34)/10000)&"억"&IF(MOD(SUM(E34:CA34),10000)=0,"",TEXT(MOD(SUM(E34:CA34),10000),"#,##0")&"만원"), TEXT(SUM(E34:CA34),"#,##0")&"만원")) -> 1,000만원 | E34: 1000
B35: 급성심근경색 진단 | D35: =IF(SUM(E35:CA35)=0,"", IF(SUM(E35:CA35)>=10000, INT(SUM(E35:CA35)/10000)&"억"&IF(MOD(SUM(E35:CA35),10000)=0,"",TEXT(MOD(SUM(E35:CA35),10000),"#,##0")&"만원"), TEXT(SUM(E35:CA35),"#,##0")&"만원"))
B36: 혈전용해치료비 | D36: =IF(SUM(E36:CA36)=0,"", IF(SUM(E36:CA36)>=10000, INT(SUM(E36:CA36)/10000)&"억"&IF(MOD(SUM(E36:CA36),10000)=0,"",TEXT(MOD(SUM(E36:CA36),10000),"#,##0")&"만원"), TEXT(SUM(E36:CA36),"#,##0")&"만원"))
B37: 허혈성심장 수술비 | D37: =IF(SUM(E37:CA37)=0,"", IF(SUM(E37:CA37)>=10000, INT(SUM(E37:CA37)/10000)&"억"&IF(MOD(SUM(E37:CA37),10000)=0,"",TEXT(MOD(SUM(E37:CA37),10000),"#,##0")&"만원"), TEXT(SUM(E37:CA37),"#,##0")&"만원"))
B38: 2대 주요 치료비 | D38: =IF(SUM(E38:CA38)=0,"", IF(SUM(E38:CA38)>=10000, INT(SUM(E38:CA38)/10000)&"억"&IF(MOD(SUM(E38:CA38),10000)=0,"",TEXT(MOD(SUM(E38:CA38),10000),"#,##0")&"만원"), TEXT(SUM(E38:CA38),"#,##0")&"만원")) -> 2,000만원 | E38: 2000
A39: 수술 | B39: 질병 수술비 | D39: =IF(SUM(E39:CA39)=0,"", IF(SUM(E39:CA39)>=10000, INT(SUM(E39:CA39)/10000)&"억"&IF(MOD(SUM(E39:CA39),10000)=0,"",TEXT(MOD(SUM(E39:CA39),10000),"#,##0")&"만원"), TEXT(SUM(E39:CA39),"#,##0")&"만원")) -> 100만원 | E39: 100
B40: 질병 종 수술비 | D40: 직접입력
...

Sheet 담보별 가입금액
E1: =표지!C3 -> 홍길동 | G1: 고객님 담보별 가입금액 | O1: ⬇️ 현재 보장 수정
O2: 보장분석!Print_Area
B6: 사망 | F6: 후유장해 | J6: 치매/ 간병
B7: =보장분석!B9 -> 일반사망 | D7: =보장분석!D9 -> 3,000만원 | F7: =보장분석!B12 -> 질병후유장해(3%) | H7: =보장분석!D12 | J7: =보장분석!B16 -> 경증 치매 진단 | L7: =보장분석!D16
B8: =보장분석!B10 -> 질병사망 | D8: =보장분석!D10 | F8: =보장분석!B13 -> 질병후유장해(80%) | H8: =보장분석!D13 | J8: =보장분석!B17 -> 시설급여 | L8: =보장분석!D17
B9: =보장분석!B11 -> 상해사망 | D9: =보장분석!D11 | F9: =보장분석!B14 -> 상해후유장해(3%) | H9: =보장분석!D14 | J9: =보장분석!B18 -> 재가급여 | L9: =보장분석!D18
D10: =보장분석!D12 | F10: =보장분석!B15 -> 상해후유장해(80%) | H10: =보장분석!D15 | J10: =보장분석!B19 -> 질병 간병인 일당 | L10: =보장분석!D19
D11: =보장분석!D13 | H11: =보장분석!D16 | J11: =보장분석!B20 -> 상해 간병인 일당 | L11: =보장분석!D20
B14: 암 | F14: 뇌 | J14: 심장
B15: =보장분석!B21 -> 일반암 진단 | D15: =보장분석!D21 -> 3,000만원 | F15: =보장분석!B27 -> 뇌혈관질환 진단 | H15: =보장분석!D27 -> 1,000만원 | J15: =보장분석!B33 -> 심혈관질환 진단 | L15: =보장분석!D33
B16: =보장분석!B22 -> 유사암 진단 | D16: =보장분석!D22 -> 600만원 | F16: =보장분석!B28 -> 뇌졸증 진단 | H16: =보장분석!D28 | J16: =보장분석!B34 -> 허혈성심장 진단 | L16: =보장분석!D34
B17: =보장분석!B23 -> 암 주요 치료비 | D17: =보장분석!D23 | F17: =보장분석!B29 -> 뇌출혈 진단 | H17: =보장분석!D29 -> 3,000만원 | J17: =보장분석!B35 -> 급성심근경색 진단 | L17: =보장분석!D35 -> 3,000만원
B18: =보장분석!B24 -> 중입자 치료비 | D18: =보장분석!D24 | F18: =보장분석!B30 -> 혈전용해치료비 | H18: =보장분석!D30 | J18: =보장분석!B36 -> 혈전용해치료비 | L18: =보장분석!D36
B19: =보장분석!B25 -> 항암 방사선 치료비 | D19: =보장분석!D25 -> 1억 | F19: =보장분석!B31 -> 뇌혈관 수술비 | H19: =보장분석!D31 -> 1,000만원 | J19: =보장분석!B37 -> 허혈성심장 수술비 | L19: =보장분석!D37 -> 1,000만원
B20: =보장분석!B26 -> 항암 약물 치료비 | D20: =보장분석!D26 -> 1억 | F20: =보장분석!B32 -> 2대 주요 치료비 | H20: =보장분석!D32 | J20: =보장분석!B38 -> 2대 주요 치료비 | L20: =보장분석!D38
B23: 수술 | F23: 입원 | J23: 골절 / 화상
B24: =보장분석!B39 -> 질병 수술비 | D24: =보장분석!D39 -> 50만원 | F24: =보장분석!B44 -> 질병 입원 | H24: =보장분석!D44 -> 1만원 | J24: =보장분석!B50 -> 깁스 | L24: =보장분석!D50 -> 50만원
B25: =보장분석!B40 -> 질병 종 수술비 | D25: =보장분석!D40 -> 직접입력 | F25: =보장분석!B45 -> 상해 입원 | H25: =보장분석!D45 -> 1만원 | J25: =보장분석!B51 -> 골절진단 | L25: =보장분석!D51 -> 50만원
B26: =보장분석!B41 -> N대 수술비 | D26: =보장분석!D41 -> 직접입력 | F26: =보장분석!B46 -> 질병 간호간병통합 | H26: =보장분석!D46 | J26: =보장분석!B52 -> 5대골절진단 | L26: =보장분석!D52 -> 100만원
B27: =보장분석!B42 -> 상해 수술비 | D27: =보장분석!D42 | F27: =보장분석!B47 -> 상해 간호간병통합 | H27: =보장분석!D47 | J27: =보장분석!B53 -> 화상진단 | L27: =보장분석!D53 -> 30만원
B28: =보장분석!B43 -> 상해 종 수술비 | D28: =보장분석!D43 -> 직접입력 | F28: =보장분석!B48 -> 상급종합병원 | H28: =보장분석!D48
F29: =보장분석!B49 -> 종합병원 | H29: =보장분석!D49
B32: 운전자 | F32: 실손의료비 | J32: 배상
B33: =보장분석!B54 -> 벌금(대인) | D33: =보장분석!D54 | F33: =보장분석!B60 -> 질병입원 의료비 | H33: =보장분석!D60 | J33: =보장분석!B59 -> 일상생활배상책임 | L33: =보장분석!D59
B34: =보장분석!B55 -> 벌금(대물) | D34: =보장분석!D55 | F34: =보장분석!B61 -> 질병통원 의료비 | H34: =보장분석!D61
B35: =보장분석!B56 -> 교통사고처리지원금 | D35: =보장분석!D56 | F35: =보장분석!B62 -> 상해입원 의료비 | H35: =보장분석!D62
B36: =보장분석!B57 -> 변호사선임비용 | D36: =보장분석!D57 | F36: =보장분석!B63 -> 상해통원 의료비 | H36: =보장분석!D63
B37: =보장분석!B58 -> 자동차사고부상치료비 | D37: =보장분석!D58
C40: =표지!C3 -> 홍길동 | F40: 고객님의 월 납입 보험료 | I40: =보장분석!A5 -> 150000
E41: 총 납입 예정 보험료 | H41: =SUM(보장분석!E6:CA6) -> 53550000

Sheet 리모델링 후(담보)
E1: =표지!C3 -> 홍길동 | G1: 고객님 담보별 가입금액 | O1: ⬇️ 리모델링 후 보장 수정
O2: 리모델링 후(보장)'!Print_Area
L5: ※ 리모델링 후
B6: 사망 | F6: 후유장해 | J6: 치매/ 간병
B7: ='리모델링 후(보장)'!B9 -> 일반사망 | D7: ='리모델링 후(보장)'!D9 | F7: ='리모델링 후(보장)'!B12 -> 질병후유장해(3%) | H7: ='리모델링 후(보장)'!D12 | J7: ='리모델링 후(보장)'!B16 -> 경증 치매 진단 | L7: ='리모델링 후(보장)'!D16
B8: ='리모델링 후(보장)'!B10 -> 질병사망 | D8: ='리모델링 후(보장)'!D10 | F8: ='리모델링 후(보장)'!B13 -> 질병후유장해(80%) | H8: ='리모델링 후(보장)'!D13 | J8: ='리모델링 후(보장)'!B17 -> 시설급여 | L8: ='리모델링 후(보장)'!D17
B9: ='리모델링 후(보장)'!B11 -> 상해사망 | D9: ='리모델링 후(보장)'!D11 | F9: ='리모델링 후(보장)'!B14 -> 상해후유장해(3%) | H9: ='리모델링 후(보장)'!D14 | J9: ='리모델링 후(보장)'!B18 -> 재가급여 | L9: ='리모델링 후(보장)'!D18
D10: ='리모델링 후(보장)'!D12 | F10: ='리모델링 후(보장)'!B15 -> 상해후유장해(80%) | H10: ='리모델링 후(보장)'!D15 | J10: ='리모델링 후(보장)'!B19 -> 질병 간병인 일당 | L10: ='리모델링 후(보장)'!D19 -> 15만원
D11: ='리모델링 후(보장)'!D13 | H11: ='리모델링 후(보장)'!D16 | J11: ='리모델링 후(보장)'!B20 -> 상해 간병인 일당 | L11: ='리모델링 후(보장)'!D20 -> 15만원
B14: 암 | F14: 뇌 | J14: 심장
B15: ='리모델링 후(보장)'!B21 -> 일반암 진단 | D15: ='리모델링 후(보장)'!D21 -> 5,000만원 | F15: ='리모델링 후(보장)'!B27 -> 뇌혈관질환 진단 | H15: ='리모델링 후(보장)'!D27 -> 1,000만원 | J15: ='리모델링 후(보장)'!B33 -> 심혈관질환 진단 | L15: ='리모델링 후(보장)'!D33 -> 1,000만원
B16: ='리모델링 후(보장)'!B22 -> 유사암 진단 | D16: ='리모델링 후(보장)'!D22 -> 1,000만원 | F16: ='리모델링 후(보장)'!B28 -> 뇌졸증 진단 | H16: ='리모델링 후(보장)'!D28 -> 1,000만원 | J16: ='리모델링 후(보장)'!B34 -> 허혈성심장 진단 | L16: ='리모델링 후(보장)'!D34 -> 1,000만원
B17: ='리모델링 후(보장)'!B23 -> 암 주요 치료비 | D17: ='리모델링 후(보장)'!D23 -> 1,000만원 | F17: ='리모델링 후(보장)'!B29 -> 뇌출혈 진단 | H17: ='리모델링 후(보장)'!D29 | J17: ='리모델링 후(보장)'!B35 -> 급성심근경색 진단 | L17: ='리모델링 후(보장)'!D35
B18: ='리모델링 후(보장)'!B24 -> 중입자 치료비 | D18: ='리모델링 후(보장)'!D24 -> 5,000만원 | F18: ='리모델링 후(보장)'!B30 -> 혈전용해치료비 | H18: ='리모델링 후(보장)'!D30 | J18: ='리모델링 후(보장)'!B36 -> 혈전용해치료비 | L18: ='리모델링 후(보장)'!D36
B19: ='리모델링 후(보장)'!B25 -> 항암 방사선 치료비 | D19: ='리모델링 후(보장)'!D25 | F19: ='리모델링 후(보장)'!B31 -> 뇌혈관 수술비 | H19: ='리모델링 후(보장)'!D31 | J19: ='리모델링 후(보장)'!B37 -> 허혈성심장 수술비 | L19: ='리모델링 후(보장)'!D37
B20: ='리모델링 후(보장)'!B26 -> 항암 약물 치료비 | D20: ='리모델링 후(보장)'!D26 | F20: ='리모델링 후(보장)'!B32 -> 2대 주요 치료비 | H20: ='리모델링 후(보장)'!D32 -> 2,000만원 | J20: ='리모델링 후(보장)'!B38 -> 2대 주요 치료비 | L20: ='리모델링 후(보장)'!D38 -> 2,000만원
B23: 수술 | F23: 입원 | J23: 골절 / 화상
B24: ='리모델링 후(보장)'!B39 -> 질병 수술비 | D24: ='리모델링 후(보장)'!D39 -> 100만원 | F24: ='리모델링 후(보장)'!B44 -> 질병 입원 | H24: ='리모델링 후(보장)'!D44 | J24: ='리모델링 후(보장)'!B50 -> 깁스 | L24: ='리모델링 후(보장)'!D50 -> 50만원
B25: ='리모델링 후(보장)'!B40 -> 질병 종 수술비 | D25: ='리모델링 후(보장)'!D40 -> 직접입력 | F25: ='리모델링 후(보장)'!B45 -> 상해 입원 | H25: ='리모델링 후(보장)'!D45 | J25: ='리모델링 후(보장)'!B51 -> 골절진단 | L25: ='리모델링 후(보장)'!D51 -> 50만원
B26: ='리모델링 후(보장)'!B41 -> N대 수술비 | D26: ='리모델링 후(보장)'!D41 -> 직접입력 | F26: ='리모델링 후(보장)'!B46 -> 질병 간호간병통합 | H26: ='리모델링 후(보장)'!D46 -> 7만원 | J26: ='리모델링 후(보장)'!B52 -> 5대골절진단 | L26: ='리모델링 후(보장)'!D52 -> 100만원
B27: ='리모델링 후(보장)'!B42 -> 상해 수술비 | D27: ='리모델링 후(보장)'!D42 -> 100만원 | F27: ='리모델링 후(보장)'!B47 -> 상해 간호간병통합 | H27: ='리모델링 후(보장)'!D47 -> 7만원 | J27: ='리모델링 후(보장)'!B53 -> 화상진단 | L27: ='리모델링 후(보장)'!D53 -> 50만원
B28: ='리모델링 후(보장)'!B43 -> 상해 종 수술비 | D28: ='리모델링 후(보장)'!D43 -> 직접입력 | F28: ='리모델링 후(보장)'!B48 -> 상급종합병원 | H28: ='리모델링 후(보장)'!D48 -> 40만원
F29: ='리모델링 후(보장)'!B49 -> 종합병원 | H29: ='리모델링 후(보장)'!D49 -> 20만원
B32: 운전자 | F32: 실손의료비 | J32: 배상
B33: ='리모델링 후(보장)'!B54 -> 벌금(대인) | D33: ='리모델링 후(보장)'!D54 | F33: ='리모델링 후(보장)'!B60 -> 질병입원 의료비 | H33: ='리모델링 후(보장)'!D60 | J33: ='리모델링 후(보장)'!B59 -> 일상생활배상책임 | L33: ='리모델링 후(보장)'!D59
B34: ='리모델링 후(보장)'!B55 -> 벌금(대물) | D34: ='리모델링 후(보장)'!D55 | F34: ='리모델링 후(보장)'!B61 -> 질병통원 의료비 | H34: ='리모델링 후(보장)'!D61
B35: ='리모델링 후(보장)'!B56 -> 교통사고처리지원금 | D35: ='리모델링 후(보장)'!D56 | F35: ='리모델링 후(보장)'!B62 -> 상해입원 의료비 | H35: ='리모델링 후(보장)'!D62
B36: ='리모델링 후(보장)'!B57 -> 변호사선임비용 | D36: ='리모델링 후(보장)'!D57 | F36: ='리모델링 후(보장)'!B63 -> 상해통원 의료비 | H36: ='리모델링 후(보장)'!D63
B37: ='리모델링 후(보장)'!B58 -> 자동차사고부상치료비 | D37: ='리모델링 후(보장)'!D58
D40: =표지!C3 -> 홍길동 | F40: 고객님의 월 납입 보험료 | I40: ='리모델링 후(보장)'!A5 -> 100000
E41: 총 납입 예정 보험료 | H41: =SUM('리모델링 후(보장)'!E6:CA6) -> 23700000

Sheet 리모델링 전 후 비교제안서
D1: =표지!C3 -> 홍길동 | G1: 고객님 리모델링 비교제안서 | R1: ⬇️ 현재 보장 수정 | U1: ⬇️ 리모델링 후 보장 수정
R2: 보장분석!Print_Area | U2: 리모델링 후(보장)'!Print_Area
C6: 현재 | J6: 리모델링 후
B10: 암 | C10: =보장분석!B21 -> 일반암 진단 | G10: =보장분석!D21 -> 3,000만원 | J10: ='리모델링 후(보장)'!B21 -> 일반암 진단 | N10: ='리모델링 후(보장)'!D21 -> 5,000만원
C11: =보장분석!B22 -> 유사암 진단 | G11: =보장분석!D22 -> 600만원 | J11: ='리모델링 후(보장)'!B22 -> 유사암 진단 | N11: ='리모델링 후(보장)'!D22 -> 1,000만원
C12: =보장분석!B23 -> 암 주요 치료비 | G12: =보장분석!D23 | J12: ='리모델링 후(보장)'!B23 -> 암 주요 치료비 | N12: ='리모델링 후(보장)'!D23 -> 1,000만원
C13: =보장분석!B24 -> 중입자 치료비 | G13: =보장분석!D24 | J13: ='리모델링 후(보장)'!B24 -> 중입자 치료비 | N13: ='리모델링 후(보장)'!D24 -> 5,000만원
C14: =보장분석!B25 -> 항암 방사선 치료비 | G14: =보장분석!D25 -> 1억 | J14: ='리모델링 후(보장)'!B25 -> 항암 방사선 치료비 | N14: ='리모델링 후(보장)'!D25
C15: =보장분석!B26 -> 항암 약물 치료비 | G15: =보장분석!D26 -> 1억 | J15: ='리모델링 후(보장)'!B26 -> 항암 약물 치료비 | N15: ='리모델링 후(보장)'!D26
B16: 뇌 | C16: =보장분석!B27 -> 뇌혈관질환 진단 | G16: =보장분석!D27 -> 1,000만원 | J16: ='리모델링 후(보장)'!B27 -> 뇌혈관질환 진단 | N16: ='리모델링 후(보장)'!D27 -> 1,000만원
C17: =보장분석!B28 -> 뇌졸증 진단 | G17: =보장분석!D28 | J17: ='리모델링 후(보장)'!B28 -> 뇌졸증 진단 | N17: ='리모델링 후(보장)'!D28 -> 1,000만원
C18: =보장분석!B29 -> 뇌출혈 진단 | G18: =보장분석!D29 -> 3,000만원 | J18: ='리모델링 후(보장)'!B29 -> 뇌출혈 진단 | N18: ='리모델링 후(보장)'!D29
C19: =보장분석!B30 -> 혈전용해치료비 | G19: =보장분석!D30 | J19: ='리모델링 후(보장)'!B30 -> 혈전용해치료비 | N19: ='리모델링 후(보장)'!D30
C20: =보장분석!B31 -> 뇌혈관 수술비 | G20: =보장분석!D31 -> 1,000만원 | J20: ='리모델링 후(보장)'!B31 -> 뇌혈관 수술비 | N20: ='리모델링 후(보장)'!D31
C21: =보장분석!B32 -> 2대 주요 치료비 | G21: =보장분석!D32 | J21: ='리모델링 후(보장)'!B32 -> 2대 주요 치료비 | N21: ='리모델링 후(보장)'!D32 -> 2,000만원
B22: 심장 | C22: =보장분석!B33 -> 심혈관질환 진단 | G22: =보장분석!D33 | J22: ='리모델링 후(보장)'!B33 -> 심혈관질환 진단 | N22: ='리모델링 후(보장)'!D33 -> 1,000만원
C23: =보장분석!B34 -> 허혈성심장 진단 | G23: =보장분석!D34 | J23: ='리모델링 후(보장)'!B34 -> 허혈성심장 진단 | N23: ='리모델링 후(보장)'!D34 -> 1,000만원
C24: =보장분석!B35 -> 급성심근경색 진단 | G24: =보장분석!D35 -> 3,000만원 | J24: ='리모델링 후(보장)'!B35 -> 급성심근경색 진단 | N24: ='리모델링 후(보장)'!D35
C25: =보장분석!B36 -> 혈전용해치료비 | G25: =보장분석!D36 | J25: ='리모델링 후(보장)'!B36 -> 혈전용해치료비 | N25: ='리모델링 후(보장)'!D36
C26: =보장분석!B37 -> 허혈성심장 수술비 | G26: =보장분석!D37 -> 1,000만원 | J26: ='리모델링 후(보장)'!B37 -> 허혈성심장 수술비 | N26: ='리모델링 후(보장)'!D37
C27: =보장분석!B38 -> 2대 주요 치료비 | G27: =보장분석!D38 | J27: ='리모델링 후(보장)'!B38 -> 2대 주요 치료비 | N27: ='리모델링 후(보장)'!D38 -> 2,000만원
B28: 수술 | C28: =보장분석!B39 -> 질병 수술비 | G28: =보장분석!D39 -> 50만원 | J28: ='리모델링 후(보장)'!B39 -> 질병 수술비 | N28: ='리모델링 후(보장)'!D39 -> 100만원
C29: =보장분석!B40 -> 질병 종 수술비 | G29: =보장분석!D40 -> 직접입력 | J29: ='리모델링 후(보장)'!B40 -> 질병 종 수술비 | N29: ='리모델링 후(보장)'!D40 -> 직접입력
C30: =보장분석!B41 -> N대 수술비 | G30: =보장분석!D41 -> 직접입력 | J30: ='리모델링 후(보장)'!B41 -> N대 수술비 | N30: ='리모델링 후(보장)'!D41 -> 직접입력
C31: =보장분석!B42 -> 상해 수술비 | G31: =보장분석!D42 | J31: ='리모델링 후(보장)'!B42 -> 상해 수술비 | N31: ='리모델링 후(보장)'!D42 -> 100만원
C32: =보장분석!B43 -> 상해 종 수술비 | G32: =보장분석!D43 -> 직접입력 | J32: ='리모델링 후(보장)'!B43 -> 상해 종 수술비 | N32: ='리모델링 후(보장)'!D43 -> 직접입력
B33: 입원 | C33: =보장분석!B44 -> 질병 입원 | G33: =보장분석!D44 -> 1만원 | J33: ='리모델링 후(보장)'!B44 -> 질병 입원 | N33: ='리모델링 후(보장)'!D44
C34: =보장분석!B45 -> 상해 입원 | G34: =보장분석!D45 -> 1만원 | J34: ='리모델링 후(보장)'!B45 -> 상해 입원 | N34: ='리모델링 후(보장)'!D45
C35: =보장분석!B46 -> 질병 간호간병통합 | G35: =보장분석!D46 | J35: ='리모델링 후(보장)'!B46 -> 질병 간호간병통합 | N35: ='리모델링 후(보장)'!D46 -> 7만원
C36: =보장분석!B47 -> 상해 간호간병통합 | G36: =보장분석!D47 | J36: ='리모델링 후(보장)'!B47 -> 상해 간호간병통합 | N36: ='리모델링 후(보장)'!D47 -> 7만원
B37: 골절 화상 | C37: =보장분석!B50 -> 깁스 | G37: =보장분석!D50 -> 50만원 | J37: ='리모델링 후(보장)'!D50 -> 50만원 | N37: ='리모델링 후(보장)'!D50 -> 50만원
C38: =보장분석!B51 -> 골절진단 | G38: =보장분석!D51 -> 50만원 | J38: ='리모델링 후(보장)'!D51 -> 50만원 | N38: ='리모델링 후(보장)'!D51 -> 50만원
C39: =보장분석!B52 -> 5대골절진단 | G39: =보장분석!D52 -> 100만원 | J39: ='리모델링 후(보장)'!D52 -> 100만원 | N39: ='리모델링 후(보장)'!D52 -> 100만원
C40: =보장분석!B53 -> 화상진단 | G40: =보장분석!D53 -> 30만원 | J40: ='리모델링 후(보장)'!D53 -> 50만원 | N40: ='리모델링 후(보장)'!D53 -> 50만원
B42: 월 보험료 | C42: =보장분석!A5 -> 150000 | J42: ='리모델링 후(보장)'!A5 -> 100000
B44: 총 납입 보험료 | C44: =SUM(보장분석!E6:CA6) -> 53550000 | J44: =SUM('리모델링 후(보장)'!E6:CA6) -> 23700000

Sheet 리모델링 요약 보고서
F1: =표지!C3 -> 홍길동 | H1: 고객님 리모델링 보고서
B6: 현재 총 보험료 | F6: =보장분석!A5 -> 150000 | I6: 리모델링 후 총 보험료 | M6: ='리모델링 후(보장)'!A5 -> 100000 | P6: ← 입력 X (자동출력)
B9: {=INDEX(보장분석!$E$1:$CA$1,1,ROW(A1))} -> 한화생명 | C9: {=INDEX(보장분석!$E$2:$CA$2,1,ROW(A1))} -> 한화생명 100세착한암보험 | G9: {=IF(INDEX(보장분석!$E$8:$CA$8,1,ROW(A1))="","", INDEX(보장분석!$E$8:$CA$8,1,ROW(A1)))} -> 150000 | I9: {=INDEX('리모델링 후(보장)'!$E$1:$CA$1,1,ROW(A1))} -> 삼성화재 | J9: {=INDEX('리모델링 후(보장)'!$E$2:$CA$2,1,ROW(A1))} -> 새로고침100세 | N9: {=IF(INDEX('리모델링 후(보장)'!$E$8:$CA$8,1,ROW(A1))="","", INDEX('리모델링 후(보장)'!$E$8:$CA$8,1,ROW(A1)))} -> 100000
B10: {=INDEX(보장분석!$E$1:$CA$1,1,ROW(A2))} -> 0 | C10: {=INDEX(보장분석!$E$2:$CA$2,1,ROW(A2))} -> 0 | G10: {=IF(INDEX(보장분석!$E$8:$CA$8,1,ROW(A2))="","", INDEX(보장분석!$E$8:$CA$8,1,ROW(A2)))} | I10: {=INDEX('리모델링 후(보장)'!$E$1:$CA$1,1,ROW(A2))} -> 0 | J10: {=INDEX('리모델링 후(보장)'!$E$2:$CA$2,1,ROW(A2))} -> 0 | N10: {=IF(INDEX('리모델링 후(보장)'!$E$8:$CA$8,1,ROW(A2))="","", INDEX('리모델링 후(보장)'!$E$8:$CA$8,1,ROW(A2)))}
B11: {=INDEX(보장분석!$E$1:$CA$1,1,ROW(A3))} -> 0 | C11: {=INDEX(보장분석!$E$2:$CA$2,1,ROW(A3))} -> 0 | G11: {=IF(INDEX(보장분석!$E$8:$CA$8,1,ROW(A3))="","", INDEX(보장분석!$E$8:$CA$8,1,ROW(A3)))} | I11: {=INDEX('리모델링 후(보장)'!$E$1:$CA$1,1,ROW(A3))} -> 0 | J11: {=INDEX('리모델링 후(보장)'!$E$2:$CA$2,1,ROW(A3))} -> 0 | N11: {=IF(INDEX('리모델링 후(보장)'!$E$8:$CA$8,1,ROW(A3))="","", INDEX('리모델링 후(보장)'!$E$8:$CA$8,1,ROW(A3)))}
B12: {=INDEX(보장분석!$E$1:$CA$1,1,ROW(A4))} -> 0 | C12: {=INDEX(보장분석!$E$2:$CA$2,1,ROW(A4))} -> 0 | G12: {=IF(INDEX(보장분석!$E$8:$CA$8,1,ROW(A4))="","", INDEX(보장분석!$E$8:$CA$8,1,ROW(A4)))} | I12: {=INDEX('리모델링 후(보장)'!$E$1:$CA$1,1,ROW(A4))} -> 0 | J12: {=INDEX('리모델링 후(보장)'!$E$2:$CA$2,1,ROW(A4))} -> 0 | N12: {=IF(INDEX('리모델링 후(보장)'!$E$8:$CA$8,1,ROW(A4))="","", INDEX('리모델링 후(보장)'!$E$8:$CA$8,1,ROW(A4)))}
B13: {=INDEX(보장분석!$E$1:$CA$1,1,ROW(A5))} -> 0 | C13: {=INDEX(보장분석!$E$2:$CA$2,1,ROW(A5))} -> 0 | G13: {=IF(INDEX(보장분석!$E$8:$CA$8,1,ROW(A5))="","", INDEX(보장분석!$E$8:$CA$8,1,ROW(A5)))} | I13: {=INDEX('리모델링 후(보장)'!$E$1:$CA$1,1,ROW(A5))} -> 0 | J13: {=INDEX('리모델링 후(보장)'!$E$2:$CA$2,1,ROW(A5))} -> 0 | N13: {=IF(INDEX('리모델링 후(보장)'!$E$8:$CA$8,1,ROW(A5))="","", INDEX('리모델링 후(보장)'!$E$8:$CA$8,1,ROW(A5)))}
B15: * 셀클릭 후 꼭짓점을 끌어 자동채우기 하시면 값 자동 입력 됩니다
D23: 보험 리모델링 후 월 보험료 | I23: =F6-M6 -> 50000 | J23: 절감
B25: 앞으로 납부해야 할 총 보험료 | H25: ='리모델링 전 후 비교제안서'!C44-'리모델링 전 후 비교제안서'!J44 -> 29850000 | J25: 이 절감 됩니다

Sheet 회사별 비교제안서(건강)
D1: =표지!C3 -> 홍길동 | G1: 고객님 건강보험 비교제안서
C6: 삼성화재 | J6: 현대해상 | Q6: ← 보험사 입력
D8: 30 | E8: 년납 | F8: 100 | G8: 만기 | K8: 20 | L8: 년납 | M8: 100 | N8: 만기 | Q8: ← 숫자만 입력
B10: 암 | C10: =보장분석!B21 -> 일반암 진단 | J10: ='리모델링 후(보장)'!B21 -> 일반암 진단 | Q10: ← 담보명 수정하여 사용 / 금액 숫자만 입력
C11: =보장분석!B22 -> 유사암 진단 | J11: ='리모델링 후(보장)'!B22 -> 유사암 진단
C12: =보장분석!B23 -> 암 주요 치료비 | J12: ='리모델링 후(보장)'!B23 -> 암 주요 치료비
C13: =보장분석!B24 -> 중입자 치료비 | J13: ='리모델링 후(보장)'!B24 -> 중입자 치료비
C14: =보장분석!B25 -> 항암 방사선 치료비 | J14: ='리모델링 후(보장)'!B25 -> 항암 방사선 치료비
C15: =보장분석!B26 -> 항암 약물 치료비 | J15: ='리모델링 후(보장)'!B26 -> 항암 약물 치료비
B16: 뇌 | C16: =보장분석!B27 -> 뇌혈관질환 진단 | J16: ='리모델링 후(보장)'!B27 -> 뇌혈관질환 진단
C17: =보장분석!B28 -> 뇌졸증 진단 | J17: ='리모델링 후(보장)'!B28 -> 뇌졸증 진단
C18: =보장분석!B29 -> 뇌출혈 진단 | J18: ='리모델링 후(보장)'!B29 -> 뇌출혈 진단
C19: =보장분석!B30 -> 혈전용해치료비 | J19: ='리모델링 후(보장)'!B30 -> 혈전용해치료비
C20: =보장분석!B31 -> 뇌혈관 수술비 | J20: ='리모델링 후(보장)'!B31 -> 뇌혈관 수술비
C21: =보장분석!B32 -> 2대 주요 치료비 | J21: ='리모델링 후(보장)'!B32 -> 2대 주요 치료비
B22: 심장 | C22: =보장분석!B33 -> 심혈관질환 진단 | J22: ='리모델링 후(보장)'!B33 -> 심혈관질환 진단
C23: =보장분석!B34 -> 허혈성심장 진단 | J23: ='리모델링 후(보장)'!B34 -> 허혈성심장 진단
C24: =보장분석!B35 -> 급성심근경색 진단 | J24: ='리모델링 후(보장)'!B35 -> 급성심근경색 진단
C25: =보장분석!B36 -> 혈전용해치료비 | J25: ='리모델링 후(보장)'!B36 -> 혈전용해치료비
C26: =보장분석!B37 -> 허혈성심장 수술비 | J26: ='리모델링 후(보장)'!B37 -> 허혈성심장 수술비
C27: =보장분석!B38 -> 2대 주요 치료비 | J27: ='리모델링 후(보장)'!B38 -> 2대 주요 치료비
B28: 수술 | C28: =보장분석!B39 -> 질병 수술비 | J28: ='리모델링 후(보장)'!B39 -> 질병 수술비
C29: =보장분석!B40 -> 질병 종 수술비 | J29: ='리모델링 후(보장)'!B40 -> 질병 종 수술비
C30: =보장분석!B41 -> N대 수술비 | J30: ='리모델링 후(보장)'!B41 -> N대 수술비
C31: =보장분석!B42 -> 상해 수술비 | J31: ='리모델링 후(보장)'!B42 -> 상해 수술비
C32: =보장분석!B43 -> 상해 종 수술비 | J32: ='리모델링 후(보장)'!B43 -> 상해 종 수술비
B33: 입원 | C33: =보장분석!B44 -> 질병 입원 | J33: ='리모델링 후(보장)'!B44 -> 질병 입원
C34: =보장분석!B45 -> 상해 입원 | J34: ='리모델링 후(보장)'!B45 -> 상해 입원
C35: =보장분석!B46 -> 질병 간호간병통합 | J35: ='리모델링 후(보장)'!B46 -> 질병 간호간병통합
C36: =보장분석!B47 -> 상해 간호간병통합 | J36: ='리모델링 후(보장)'!B47 -> 상해 간호간병통합
B37: 골절 화상 | C37: =보장분석!B50 -> 깁스 | J37: ='리모델링 후(보장)'!D50 -> 50만원
C38: =보장분석!B51 -> 골절진단 | J38: ='리모델링 후(보장)'!D51 -> 50만원
C39: =보장분석!B52 -> 5대골절진단 | J39: ='리모델링 후(보장)'!D52 -> 100만원
C40: =보장분석!B53 -> 화상진단 | J40: ='리모델링 후(보장)'!D53 -> 50만원
B42: 월 보험료 | Q42: ← 월 보험료만 입력
B44: 총 납입 보험료 | C44: =C42*12*D8 -> 0 | J44: =J42*12*K8 -> 0 | Q44: ← 자동산출

Sheet 회사별 비교제안서(운전자)
D1: =표지!C3 -> 홍길동 | G1: 고객님 운전자보험 비교제안서
C6: 삼성화재 | J6: 현대해상 | Q6: ← 보험사 입력
D8: 20 | E8: 년납 | F8: 20 | G8: 만기 | K8: 20 | L8: 년납 | M8: 20 | N8: 만기 | Q8: ← 숫자만 입력
B10: 사망 | Q10: ← 담보명 수정하여 사용 / 금액 숫자만 입력
B12: 후유장해
B16: 골절 화상
B21: 수술
B26: 입원
B30: 법률비용 | C30: 벌금 (대인)
C31: 벌금 (대물)
C32: 교통사고처리지원금
C33: 변호사선임비용
B35: 자부상 | C35: 1-7급
C36: 14급
B38: 기타 | C38: 일상배상책임
B42: 월 보험료 | Q42: ← 월 보험료만 입력
B44: 총 납입 보험료 | C44: =C42*12*D8 -> 0 | J44: =J42*12*K8 -> 0 | Q44: ← 자동산출

Sheet 가족 보험 현황
E2: =표지!C3 -> 홍길동 | F2: 고객님 가족 보험 현황
A6: 구분 | B6: 계약자 | C6: 피보험자 | D6: 보험사 | E6: 보험명 | F6: 납입기간 | G6: 보장시작 | H6: 보장종료 | I6: 보험료 | J6: 비고
A7: 배우자
H14: 총 보험료 | I14: =SUM(I7:I12) -> 0
A16: 구분 | B16: 계약자 | C16: 피보험자 | D16: 보험사 | E16: 보험명 | F16: 납입기간 | G16: 보장시작 | H16: 보장종료 | I16: 보험료 | J16: 비고
A17: 자녀
H24: 총 보험료 | I24: =SUM(I17:I22) -> 0
A26: 구분 | B26: 계약자 | C26: 피보험자 | D26: 보험사 | E26: 보험명 | F26: 납입기간 | G26: 보장시작 | H26: 보장종료 | I26: 보험료 | J26: 비고
A27: 부
H34: 총 보험료 | I34: =SUM(I27:I32) -> 0
A36: 구분 | B36: 계약자 | C36: 피보험자 | D36: 보험사 | E36: 보험명 | F36: 납입기간 | G36: 보장시작 | H36: 보장종료 | I36: 보험료 | J36: 비고
A37: 모
H44: 총 보험료 | I44: =SUM(I37:I42) -> 0

Sheet 만족도 조사
A1: 상담 만족도 조사
A3: ⭐ 상담 만족도 평가
A5: 질문 | F5: 만족 | G5: 보통 | H5: 불만족
A6: 1. 상담내용은 이해하기 쉬웠나요?
A8: 2. 현재 보장상태를 파악하는데 도움이 되었나요?
A10: 3. 나의 상황에 맞는 맞춤 보장설계가 이루어졌나요?
A12: 3. 제안 내용에 대해 신뢰가 가셨나요?
A14: 5. 주변에 소개하고 싶은 상담이라고 느끼셨나요?
A17: ⭐ 자유로운 의견을 남겨 주세요 !
A19: - 상담 중 가장 도움이 되었던 부분은 무엇인가요?
A21: - 추가로 궁금하신 점이나 필요한 보장이 있나요?
A24: ⭐ 소중한 지인 추천
A25: 상담에 만족하셨다면 주변의 소중한 분에게도 보험 점검의 기회를 선물해 주세요 !
A27: 관계 | B27: 성함 | C27: 연락처 | F27: 메모

Sheet 표지 그래프
A1: 보장 (질병) | B1: 가입금액 | C1: 기준금액 | D1: 점수
A2: 후유장해 | B2: =SUM(보장분석!E12:CA12) -> 0 | C2: 10000 | D2: =MIN(5,B2/C2) -> 0
A3: 암 | B3: =SUM(보장분석!E21:CA21) -> 3000 | C3: 10000 | D3: =MIN(5,B3/C3) -> 0.3
A4: 심장 | B4: =SUM(보장분석!E33:CA34) -> 0 | C4: 3000 | D4: =MIN(5,B4/C4) -> 0
A5: 뇌 | B5: =SUM(보장분석!E27:CA27) -> 1000 | C5: 3000 | D5: =MIN(5,B5/C5) -> 0.33333333
A6: 수술 | B6: =SUM(보장분석!E39:CA39) -> 50 | C6: 100 | D6: =MIN(5,B6/C6) -> 0.5
A7: 입원 | B7: =SUM(보장분석!E44:CA44) -> 1 | C7: 10 | D7: =MIN(5,B7/C7) -> 0.1
A8: 수정금지 | C8: 수정가능 | D8: 수정금지
